Workbook

Sheet 月度培训数据-经理复盘会
A1: 营销中心《月度培训数据》
A2: 统计规则：商学院系统数据
A3: 月份 | B3: 城市 | C3: 培训类别 | D3: 线下培训（集团） | L3: 自主培训 | O3: 商学院
D4: 计划完成场次 （天数） | E4: 培训场次 （累计天数） | F4: 完成率（%） | G4: 培训人数（累计） | H4: 到场率 （平均） | I4: 考试平均分 （累计） | J4: 讲师满意度 （平均） | K4: 课程满意度 （平均） | L4: 培训场次（累计） | M4: 培训人数（累计） | N4: 讲师满意度 （平均） | O4: 《每日一练》 | R4: 《每周一通》 | U4: 《每周一练》
O5: 应完成数量 | P5: 实际完成数量 | Q5: 完成率 | R5: 应完成数量 | S5: 实际完成数量 | T5: 完成率 | U5: 应完成数量 | V5: 实际完成数量 | W5: 完成率
A6: 1月 | B6: 甘肃 | C6: 销售新人入职培训 | D6: 1 | E6: 1 | F6: 1 | G6: 1 | H6: 1 | I6: 97.5 | J6: 5 | K6: 5 | L6: 9 | M6: 33 | N6: 5 | O6: 111 | P6: 104 | Q6: =P6/O6 -> 0.93693694 | R6: 15 | S6: 15 | T6: =S6/R6 -> 1 | U6: 4 | V6: 4 | W6: =V6/U6 -> 1
A7: 1月 | B7: 河北 | C7: 销售新人入职培训 | D7: 1 | E7: 3 | F7: 1 | G7: 3 | H7: 0.75 | I7: 62.3125 | J7: 5 | K7: 5 | L7: 12 | M7: 32 | N7: 5 | O7: 383 | P7: 374 | Q7: =P7/O7 -> 0.97650131 | R7: 58 | S7: 57 | T7: =S7/R7 -> 0.98275862 | U7: 16 | V7: 16 | W7: =V7/U7 -> 1
C8: 销售提升训 | D8: 1 | F8: 1 | G8: 2 | H8: 1 | I8: 82.333333 | J8: 5 | K8: 5
C9: 销售经理培训 | D9: 1 | F9: 1 | G9: 2 | H9: 1 | I9: 0 | J9: 5 | K9: 5
A10: 1月 | B10: 河南 | C10: 销售新人入职培训 | D10: 1 | E10: 9 | F10: 1 | G10: 5 | H10: 0.83333333 | I10: 76.875 | J10: 5 | K10: 5 | L10: 21 | M10: 95 | N10: 5 | O10: 845 | P10: 776 | Q10: =P10/O10 -> 0.9183432 | R10: 127 | S10: 125 | T10: =S10/R10 -> 0.98425197 | U10: 28 | V10: 25 | W10: =V10/U10 -> 0.89285714
C11: 销售提升训 | D11: 1 | F11: 1 | G11: 3 | H11: 1 | I11: 85.888889 | J11: 5 | K11: 5
C12: B岗培训 | D12: 6 | F12: 1 | G12: 3 | H12: 1 | I12: 0 | J12: 5 | K12: 5
C13: 销售经理培训 | D13: 1 | F13: 1 | G13: 3 | H13: 1 | I13: 0 | J13: 5 | K13: 5
A14: 1月 | B14: 湖北 | C14: 销售新人入职培训 | D14: 1 | E14: 9 | F14: 1 | G14: 3 | H14: 1 | I14: 92.083333 | J14: 5 | K14: 5 | L14: 38 | M14: 125 | N14: 5 | O14: 1389 | P14: 1313 | Q14: =P14/O14 -> 0.94528438 | R14: 206 | S14: 199 | T14: =S14/R14 -> 0.96601942 | U14: 46 | V14: 43 | W14: =V14/U14 -> 0.93478261
C15: 销售提升训 | D15: 1 | F15: 1 | G15: 0 | H15: 0 | I15: 0 | J15: 0 | K15: 0
C16: B岗培训 | D16: 6 | F16: 1 | G16: 12 | H16: 1 | I16: 0 | J16: 5 | K16: 5
C17: 销售经理培训 | D17: 1 | F17: 1 | G17: 3 | H17: 1 | I17: 0 | J17: 5 | K17: 5
A18: 1月 | B18: 湖南 | C18: 销售新人入职培训 | D18: 1 | E18: 9 | F18: 1 | G18: 3 | H18: 0.5 | I18: 47.375 | J18: 5 | K18: 5 | L18: 37 | M18: 119 | N18: 5 | O18: 1094 | P18: 1052 | Q18: =P18/O18 -> 0.96160878 | R18: 160 | S18: 152 | T18: =S18/R18 -> 0.95 | U18: 44 | V18: 42 | W18: =V18/U18 -> 0.95454545
C19: 销售提升训 | D19: 1 | F19: 1 | G19: 2 | H19: 1 | I19: 49 | J19: 5 | K19: 5
C20: B岗培训 | D20: 6 | F20: 1 | G20: 18 | H20: 1 | I20: 0 | J20: 5 | K20: 5
C21: 销售经理培训 | D21: 1 | F21: 1 | G21: 4 | H21: 1 | I21: 0 | J21: 5 | K21: 5
A22: 1月 | B22: 辽宁 | C22: 销售提升训 | D22: 1 | E22: 2 | F22: 1 | G22: 1 | H22: 1 | I22: 80 | J22: 5 | K22: 5 | L22: 3 | M22: 15 | N22: 5 | O22: 122 | P22: 115 | Q22: =P22/O22 -> 0.94262295 | R22: 20 | S22: 20 | T22: =S22/R22 -> 1 | U22: 4 | V22: 4 | W22: =V22/U22 -> 1
C23: 销售经理培训 | D23: 1 | F23: 1 | G23: 2 | H23: 1 | I23: 0 | J23: 5 | K23: 5
A24: 1月 | B24: 内蒙古 | C24: 销售新人入职培训 | D24: 1 | E24: 1 | F24: 1 | G24: 3 | H24: 1 | I24: 76.75 | J24: 5 | K24: 5 | L24: 6 | M24: 21 | N24: 5 | O24: 213 | P24: 202 | Q24: =P24/O24 -> 0.94835681 | R24: 32 | S24: 31 | T24: =S24/R24 -> 0.96875 | U24: 8 | V24: 8 | W24: =V24/U24 -> 1
A25: 1月 | B25: 山东 | C25: 销售新人入职培训 | D25: 1 | E25: 9 | F25: 1 | G25: 2 | H25: 1 | I25: 93.75 | J25: 5 | K25: 5 | L25: 31 | M25: 119 | N25: 5 | O25: 1041 | P25: 1009 | Q25: =P25/O25 -> 0.96926033 | R25: 152 | S25: 151 | T25: =S25/R25 -> 0.99342105 | U25: 38 | V25: 37 | W25: =V25/U25 -> 0.97368421
C26: 销售提升训 | D26: 1 | F26: 1 | G26: 6 | H26: 1 | I26: 92.705882 | J26: 5 | K26: 5
C27: B岗培训 | D27: 6 | F27: 1 | G27: 18 | H27: 1 | I27: 0 | J27: 5 | K27: 5
C28: 销售经理培训 | D28: 1 | F28: 1 | G28: 3 | H28: 1 | I28: 0 | J28: 5 | K28: 5
A29: 1月 | B29: 山西 | C29: 销售提升训 | D29: 1 | E29: 8 | F29: 1 | G29: 6 | H29: 1 | I29: 83.166667 | J29: 5 | K29: 5 | L29: 23 | M29: 108 | N29: 5 | O29: 1004 | P29: 933 | Q29: =P29/O29 -> 0.92928287 | R29: 152 | S29: 148 | T29: =S29/R29 -> 0.97368421 | U29: 30 | V29: 29 | W29: =V29/U29 -> 0.96666667
C30: B岗培训 | D30: 6 | F30: 1 | G30: 6 | H30: 1 | I30: 0 | J30: 5 | K30: 5
C31: 销售经理培训 | D31: 1 | F31: 1 | G31: 3 | H31: 1 | I31: 0 | J31: 5 | K31: 5
A32: 1月 | B32: 陕西 | C32: 销售新人入职培训 | D32: 1 | E32: 9 | F32: 1 | G32: 4 | H32: 1 | I32: 89.375 | J32: 5 | K32: 5 | L32: 50 | M32: 214 | N32: 5 | O32: 2176 | P32: 2070 | Q32: =P32/O32 -> 0.95128676 | R32: 330 | S32: 319 | T32: =S32/R32 -> 0.96666667 | U32: 76 | V32: 75 | W32: =V32/U32 -> 0.98684211
C33: 销售提升训 | D33: 1 | F33: 1 | G33: 3 | H33: 0.75 | I33: 72.75 | J33: 5 | K33: 5
C34: B岗培训 | D34: 6 | F34: 1 | G34: 18 | H34: 1 | I34: 0 | J34: 5 | K34: 5
C35: 销售经理培训 | D35: 1 | F35: 1 | G35: 4 | H35: 1 | I35: 0 | J35: 5 | K35: 5
A36: 1月 | B36: 西南总部 | C36: 销售新人入职培训 | D36: 1 | E36: 9 | F36: 1 | G36: 17 | H36: 0.31481481 | I36: 26.912821 | J36: 5 | K36: 5 | L36: 169 | M36: 732 | N36: 5 | O36: 6601 | P36: 6347 | Q36: =P36/O36 -> 0.96152098 | R36: 990 | S36: 959 | T36: =S36/R36 -> 0.96868687 | U36: 215 | V36: 207 | W36: =V36/U36 -> 0.9627907
C37: 销售提升训 | D37: 1 | F37: 1 | G37: 18 | H37: 0.32727273 | I37: 34.04908 | J37: 5 | K37: 5
C38: B岗培训 | D38: 6 | F38: 1 | G38: 50 | H38: 1 | I38: 0 | J38: 5 | K38: 5
C39: 销售经理培训 | D39: 1 | F39: 1 | G39: 11 | H39: 1 | I39: 0 | J39: 5 | K39: 5
A40: 2月 | B40: 西南总部 | C40: 讲师TTT培训 | D40: 2 | E40: 2 | F40: 1 | G40: 26 | H40: 1 | I40: 0 | J40: 0 | K40: 0 | L40: 112 | M40: 471 | N40: 4.9 | O40: 5523 | P40: 5309 | Q40: 0.96125294 | R40: 1005 | S40: 975 | T40: =S40/R40 -> 0.97014925 | U40: 219 | V40: 211 | W40: =V40/U40 -> 0.96347032
...

Sheet 自主培训2026年度数据（累计）
A1: 自主培训(1-2月） | P1: 月份 | Q1: 城市 | R1: 自主培训
A2: 地区 | B2: 月份 | C2: 培训日期 | D2: 项目经理 | E2: 营业部 | F2: 项目名称 | G2: 培训课程 | H2: 讲师满意度 | I2: 已签到人数 | J2: 是否合格 | K2: APP签到 | L2: 笔记上传 | M2: 满意度反馈 | R2: 应培训场次（累计） 经理数*3 | S2: 培训场次（累计） | T2: 培训人数（累计） | U2: 合格场次数 | V2: 考核经理合格率 （合格场次/应培训场次）
A3: 西南总部 | B3: 1月 | C3: 46053 | D3: 杨威 | E3: 营业五部 | F3: 丽都国际 | G3: 项目各阶段朋友圈内容 | H3: 4.9333333 | I3: 3 | J3: 合格 | K3: √ | L3: √ | M3: √ | P3: 1月 | Q3: 西南总部 | R3: =VLOOKUP(Q3,'[2]自主培训2026年度数据（累计）'!$Q:$R,2,0) -> 162 | S3: 169 | T3: 732 | U3: 161 | V3: =U3/R3 -> 0.99382716
A4: 西南总部 | B4: 1月 | C4: 46053 | D4: 杨威 | E4: 营业五部 | F4: 丽都国际 | G4: 优秀的车位置业顾问的5要素 | H4: 4.8666667 | I4: 3 | J4: 合格 | K4: √ | L4: √ | M4: √ | P4: 1月 | Q4: 湖北 | R4: =VLOOKUP(Q4,'[2]自主培训2026年度数据（累计）'!$Q:$R,2,0) -> 42 | S4: 38 | T4: 125 | U4: 39 | V4: =U4/R4 -> 0.92857143
A5: 西南总部 | B5: 1月 | C5: 46053 | D5: 文鹏羽 | E5: 营业二部 | F5: 御府观澜阁 | G5: 加微信阶段注意事项 | H5: 5 | I5: 3 | J5: 合格 | K5: √ | L5: √ | M5: √ | P5: 1月 | Q5: 甘肃 | R5: =VLOOKUP(Q5,'[2]自主培训2026年度数据（累计）'!$Q:$R,2,0) -> 3 | S5: 9 | T5: 33 | U5: 3 | V5: 1
A6: 西南总部 | B6: 1月 | C6: 46053 | D6: 文鹏羽 | E6: 营业二部 | F6: 御府观澜阁 | G6: 回话的技术 | H6: 5 | I6: 3 | J6: 合格 | K6: √ | L6: √ | M6: √ | P6: 1月 | Q6: 湖南 | R6: =VLOOKUP(Q6,'[2]自主培训2026年度数据（累计）'!$Q:$R,2,0) -> 36 | S6: 37 | T6: 119 | U6: 36 | V6: 1
A7: 西南总部 | B7: 1月 | C7: 46053 | D7: 刘鹏 | E7: 营业七部 | F7: 海德花园 | G7: 带看流程 | H7: 5 | I7: 2 | J7: 合格 | K7: √ | L7: √ | M7: √ | P7: 1月 | Q7: 陕西 | R7: =VLOOKUP(Q7,'[2]自主培训2026年度数据（累计）'!$Q:$R,2,0) -> 57 | S7: 56 | T7: 214 | U7: 56 | V7: =U7/R7 -> 0.98245614
A8: 湖北 | B8: 1月 | C8: 46053 | D8: 阮阳 | E8: 湖北1部 | F8: 滨湖壹号 | G8: 逼定和放价技巧 | H8: 5 | I8: 2 | J8: 合格 | K8: √ | L8: √ | M8: √ | P8: 1月 | Q8: 河北 | R8: =VLOOKUP(Q8,'[2]自主培训2026年度数据（累计）'!$Q:$R,2,0) -> 12 | S8: 12 | T8: 32 | U8: 12 | V8: 1
A9: 西南总部 | B9: 1月 | C9: 46045 | D9: 柏刚 | E9: 营业二部 | F9: 山水福都北区 | G9: 成功销售之优势谈判 | H9: 5 | I9: 3 | J9: 合格 | K9: √ | L9: √ | M9: √ | P9: 1月 | Q9: 山东 | R9: =VLOOKUP(Q9,'[2]自主培训2026年度数据（累计）'!$Q:$R,2,0) -> 30 | S9: 31 | T9: 119 | U9: 30 | V9: 1
A10: 湖北 | B10: 1月 | C10: 46053 | D10: 阮阳 | E10: 湖北1部 | F10: 滨湖壹号 | G10: 顾问式销售技巧 | H10: 5 | I10: 2 | J10: 合格 | K10: √ | L10: √ | M10: √ | P10: 1月 | Q10: 河南 | R10: =VLOOKUP(Q10,'[2]自主培训2026年度数据（累计）'!$Q:$R,2,0) -> 21 | S10: 19 | T10: 95 | U10: 19 | V10: =U10/R10 -> 0.9047619
A11: 湖北 | B11: 1月 | C11: 46053 | D11: 李文 | E11: 湖北1部 | F11: 恒大翡翠华庭 | G11: 项目不得不买的理由培训 | H11: 5 | I11: 3 | J11: 合格 | K11: √ | L11: √ | M11: √ | P11: 1月 | Q11: 山西 | R11: =VLOOKUP(Q11,'[2]自主培训2026年度数据（累计）'!$Q:$R,2,0) -> 24 | S11: 23 | T11: 108 | U11: 23 | V11: =U11/R11 -> 0.95833333
A12: 湖北 | B12: 1月 | C12: 46053 | D12: 陈晓辉 | E12: 湖北2部 | F12: 澜桥公馆 | G12: 客户预期管理 | H12: 5 | I12: 3 | J12: 合格 | K12: √ | L12: √ | M12: √ | P12: 1月 | Q12: 内蒙古 | R12: =VLOOKUP(Q12,'[2]自主培训2026年度数据（累计）'!$Q:$R,2,0) -> 6 | S12: 6 | T12: 21 | U12: 6 | V12: 1
A13: 湖北 | B13: 1月 | C13: 46053 | D13: 陈晓辉 | E13: 湖北2部 | F13: 澜桥公馆 | G13: 成功销售之优势谈判 | H13: 5 | I13: 3 | J13: 合格 | K13: √ | L13: √ | M13: √ | P13: 1月 | Q13: 辽宁 | R13: 3 | S13: 3 | T13: 15 | U13: 3 | V13: 1
A14: 湖北 | B14: 1月 | C14: 46053 | D14: 陈晓辉 | E14: 湖北2部 | F14: 澜桥公馆 | G14: 带看流程的培训 | H14: 5 | I14: 3 | J14: 合格 | K14: √ | L14: √ | M14: √ | P14: 合计 | R14: 399 | S14: 399 | T14: 1613 | U14: 388 | V14: =U14/R14 -> 0.97243108
A15: 西南总部 | B15: 1月 | C15: 46053 | D15: 张萍2 | E15: 营业五部 | F15: 南充市香槟尚城 | G15: 业主关系维护技巧 | H15: 5 | I15: 5 | J15: 合格 | K15: √ | L15: √ | M15: √ | P15: 2月 | Q15: 西南总部 | R15: 110 | S15: 112 | T15: 467 | U15: 108 | V15: =U15/R15 -> 0.98181818
A16: 湖北 | B16: 1月 | C16: 46053 | D16: 李文 | E16: 湖北1部 | F16: 恒大翡翠华庭 | G16: 项目SWOT培训 | H16: 5 | I16: 3 | J16: 合格 | K16: √ | L16: √ | M16: √ | P16: 2月 | Q16: 湖北 | R16: 26 | S16: 24 | T16: 74 | U16: 24 | V16: =U16/R16 -> 0.92307692
A17: 湖北 | B17: 1月 | C17: 46053 | D17: 李文 | E17: 湖北1部 | F17: 恒大翡翠华庭 | G17: 带看流程标准培训 | H17: 5 | I17: 3 | J17: 合格 | K17: √ | L17: √ | M17: √ | P17: 2月 | Q17: 甘肃 | R17: 2 | S17: 2 | T17: 28 | U17: 2 | V17: =U17/R17 -> 1
A18: 甘肃 | B18: 1月 | C18: 46053 | D18: 王辉 | E18: 甘肃销售部 | F18: 金悦府 | G18: 客户成交技巧 | H18: 5 | I18: 4 | J18: 合格 | K18: √ | L18: √ | M18: √ | P18: 2月 | Q18: 湖南 | R18: 22 | S18: 22 | T18: 70 | U18: 22 | V18: =U18/R18 -> 1
A19: 湖南 | B19: 1月 | C19: 46053 | D19: 杨超群 | E19: 湖南销售部 | F19: 雅典名媛 | G19: 签约培训 | H19: 5 | I19: 3 | J19: 合格 | K19: √ | L19: √ | M19: √ | P19: 2月 | Q19: 陕西 | R19: 38 | S19: 38 | T19: 141 | U19: 38 | V19: =U19/R19 -> 1
A20: 陕西 | B20: 1月 | C20: 46053 | D20: 李耀 | E20: 陕西2部 | F20: 滨江花城营销中心 | G20: 销售就是一场心理战 | H20: 5 | I20: 9 | J20: 合格 | K20: √ | L20: √ | M20: √ | P20: 2月 | Q20: 河北 | R20: 8 | S20: 6 | T20: 22 | U20: 8 | V20: =U20/R20 -> 1
A21: 陕西 | B21: 1月 | C21: 46053 | D21: 蒙建 | E21: 陕西2部 | F21: 万科大都会物业办 | G21: 销售心理学实战应用 | H21: 5 | I21: 3 | J21: 合格 | K21: √ | L21: √ | M21: √ | P21: 2月 | Q21: 山东 | R21: 20 | S21: 19 | T21: 59 | U21: 20 | V21: =U21/R21 -> 1
A22: 湖南 | B22: 1月 | C22: 46053 | D22: 刘元发 | E22: 湖南销售部 | F22: 鸿大第六区 | G22: 项目合同签订POS机使用培训 | H22: 5 | I22: 4 | J22: 合格 | K22: √ | L22: √ | M22: √ | P22: 2月 | Q22: 河南 | R22: 14 | S22: 15 | T22: 66 | U22: 14 | V22: =U22/R22 -> 1
A23: 湖南 | B23: 1月 | C23: 46053 | D23: 杨超群 | E23: 湖南销售部 | F23: 雅典铭苑 | G23: 怎样应对业主说之前价格低现在价格高 | H23: 5 | I23: 3 | J23: 合格 | K23: √ | L23: √ | M23: √ | P23: 2月 | Q23: 山西 | R23: 16 | S23: 17 | T23: 80 | U23: 16 | V23: =U23/R23 -> 1
A24: 河北 | B24: 1月 | C24: 46053 | D24: 陈东2 | E24: 河北销售部 | F24: 河北金惠华苑小区 | G24: 项目撤场阶段后续处理事项 | H24: 5 | I24: 3 | J24: 合格 | K24: √ | L24: √ | M24: √ | P24: 2月 | Q24: 内蒙古 | R24: 2 | S24: 2 | T24: 3 | U24: 2 | V24: =U24/R24 -> 1
A25: 山东 | B25: 1月 | C25: 46053 | D25: 王杰 | E25: 山东销售部 | F25: 龙域天城 | G25: 项目基础知识培训 | H25: 5 | I25: 4 | J25: 合格 | K25: √ | L25: √ | M25: √ | P25: 2月 | Q25: 辽宁 | R25: 4 | S25: 4 | T25: 14 | U25: 4 | V25: =U25/R25 -> 1
A26: 陕西 | B26: 1月 | C26: 46053 | D26: 李耀 | E26: 陕西2部 | F26: 滨江花城营销中心 | G26: 为啥销冠一直有业绩 | H26: 5 | I26: 5 | J26: 合格 | K26: √ | L26: √ | M26: √ | P26: 合计 | R26: =SUM(R15:R25) -> 262 | S26: =SUM(S15:S25) -> 261 | T26: =SUM(T15:T25) -> 1024 | U26: =SUM(U15:U25) -> 258 | V26: =U26/R26 -> 0.98473282
A27: 河南 | B27: 1月 | C27: 46053 | D27: 叶鑫 | E27: 河南销售部 | F27: 世博领秀城 | G27: 如何加好微信 | H27: 5 | I27: 1 | J27: 合格 | K27: √ | L27: √ | M27: √
A28: 河南 | B28: 1月 | C28: 46053 | D28: 叶鑫 | E28: 河南销售部 | F28: 世博领秀城 | G28: 业主关系维护 | H28: 5 | I28: 1 | J28: 合格 | K28: √ | L28: √ | M28: √
A29: 湖北 | B29: 1月 | C29: 46053 | D29: 张宗铭 | E29: 湖北1部 | F29: 天纵.半岛蓝湾2期 | G29: 外呼邀约技巧培训 | H29: 5 | I29: 1 | J29: 合格 | K29: √ | L29: √ | M29: √
A30: 陕西 | B30: 1月 | C30: 46053 | D30: 冀敏 | E30: 陕西2部 | F30: 公园天下 | G30: 项目介绍视频培训 | H30: 5 | I30: 3 | J30: 合格 | K30: √ | L30: √ | M30: √
A31: 湖北 | B31: 1月 | C31: 46053 | D31: 张宗铭 | E31: 湖北1部 | F31: 天纵.半岛蓝湾2期 | G31: 外呼加微信技巧培训 | H31: 5 | I31: 1 | J31: 合格 | K31: √ | L31: √ | M31: √
A32: 陕西 | B32: 1月 | C32: 46053 | D32: 李耀 | E32: 陕西2部 | F32: 滨江花城营销中心 | G32: 销售必备的5种思维 | H32: 5 | I32: 5 | J32: 合格 | K32: √ | L32: √ | M32: √
A33: 湖北 | B33: 1月 | C33: 46053 | D33: 张宗铭 | E33: 湖北1部 | F33: 天纵.半岛蓝湾2期 | G33: app服务费录入 | H33: 5 | I33: 1 | J33: 合格 | K33: √ | L33: √ | M33: √
A34: 西南总部 | B34: 1月 | C34: 46053 | D34: 贾萍 | E34: 营业四部 | F34: 云尚花园 | G34: 签合同流程培 | H34: 5 | I34: 2 | J34: 合格 | K34: √ | L34: √ | M34: √
A35: 西南总部 | B35: 1月 | C35: 46053 | D35: 陶再阳 | E35: 营业三部 | F35: 荣城天街 | G35: 朋友圈运营 | H35: 5 | I35: 3 | J35: 合格 | K35: √ | L35: √ | M35: √
A36: 陕西 | B36: 1月 | C36: 46053 | D36: 张英 | E36: 陕西1部 | F36: 项目办公室 | G36: 签约流程培训 | H36: 5 | I36: 4 | J36: 合格 | K36: √ | L36: √ | M36: √
A37: 西南总部 | B37: 1月 | C37: 46053 | D37: 刘亮 | E37: 营业四部 | F37: 领地东原阅城 | G37: 探出客户的真实需求 | H37: 5 | I37: 4 | J37: 合格 | K37: √ | L37: √ | M37: √
A38: 甘肃 | B38: 1月 | C38: 46053 | D38: 王辉 | E38: 甘肃销售部 | F38: 金悦府项目 | G38: 如何做好微信营销 | H38: 5 | I38: 4 | J38: 合格 | K38: √ | L38: √ | M38: √
... A662: 河南 | B662: 2月 | C662: 46063 | D662: 张萍 | E662: 河南销售部 | F662: 兰台府 | G662: 成为卓越销售五大要素 | H662: 5 | I662: 4 | J662: 合格 | K662: √ | L662: √ | M662: √

Sheet 2026年度培训主表
A1: 2026年培训数据总表-明细（1-3月）
A2: 序号 | B2: 月份 | C2: 城市 | D2: 课程类型 | E2: 课程名称 | F2: 讲师 | G2: 培训方式 | H2: 培训地点 | I2: 考核方式 | J2: 培训时间 | K2: 应参训人姓名 | L2: 签到情况 | M2: 工号 | N2: 营业部 | O2: 职级 | P2: 入职时间 | Q2: 课程满意度 | R2: 讲师满意度 | S2: 考核成绩
A3: 1 | B3: 1月 | C3: 西南总部 | D3: 销售提升训 | E3: 《心态与成败》 | F3: 梁霞 | G3: 线下 | H3: 1212 | I3: app试卷考核 | J3: 46035 | K3: 蒋婷 | L3: 未签到 | M3: 01011 | N3: 营业五部 | O3: 一星销售顾问 | P3: 45970 | Q3: 0 | R3: 0 | S3: 0
A4: 2 | B4: 1月 | C4: 西南总部 | D4: 销售提升训 | E4: 《心态与成败》 | F4: 梁霞 | G4: 线下 | H4: 1212 | I4: app试卷考核 | J4: 46035 | K4: 孙智港 | L4: 未签到 | M4: 01423 | N4: 营业五部 | O4: 一星销售顾问 | P4: 45749 | Q4: 0 | R4: 0 | S4: 0
A5: 3 | B5: 1月 | C5: 西南总部 | D5: 销售提升训 | E5: 《心态与成败》 | F5: 梁霞 | G5: 线下 | H5: 1212 | I5: app试卷考核 | J5: 46035 | K5: 李裕楷 | L5: 未签到 | M5: 01412 | N5: 营业五部 | O5: 一星销售顾问 | P5: 45747 | Q5: 0 | R5: 0 | S5: 0
A6: 4 | B6: 1月 | C6: 西南总部 | D6: 销售提升训 | E6: 《心态与成败》 | F6: 梁霞 | G6: 线下 | H6: 1212 | I6: app试卷考核 | J6: 46035 | K6: 税小蓉 | L6: 已签到 | M6: 01684 | N6: 营业二部 | O6: 一星销售顾问 | P6: 45905 | Q6: 5 | R6: 5 | S6: 107
A7: 5 | B7: 1月 | C7: 陕西 | D7: 销售提升训 | E7: 《心态与成败》 | F7: 梁霞 | G7: 线下 | H7: 1212 | I7: app试卷考核 | J7: 46035 | K7: 李松 | L7: 已签到 | M7: 01689 | N7: 陕西2部 | O7: 一星销售顾问 | P7: 45910 | Q7: 5 | R7: 5 | S7: 94
A8: 6 | B8: 1月 | C8: 西南总部 | D8: 销售提升训 | E8: 《心态与成败》 | F8: 梁霞 | G8: 线下 | H8: 1212 | I8: app试卷考核 | J8: 46035 | K8: 先波 | L8: 未签到 | M8: 01512 | N8: 营业一部 | O8: 二星销售顾问 | P8: 45812 | Q8: 0 | R8: 0 | S8: 0
A9: 7 | B9: 1月 | C9: 西南总部 | D9: 销售提升训 | E9: 《心态与成败》 | F9: 梁霞 | G9: 线下 | H9: 1212 | I9: app试卷考核 | J9: 46035 | K9: 田丰 | L9: 未签到 | M9: 01500 | N9: 营业七部 | O9: 一星销售顾问 | P9: 45804 | Q9: 0 | R9: 0 | S9: 0
A10: 8 | B10: 1月 | C10: 西南总部 | D10: 销售提升训 | E10: 《心态与成败》 | F10: 梁霞 | G10: 线下 | H10: 1212 | I10: app试卷考核 | J10: 46035 | K10: 邓孝礼 | L10: 已签到 | M10: 01621 | N10: 营业四部 | O10: 一星销售顾问 | P10: 45864 | Q10: 5 | R10: 5 | S10: 87
A11: 9 | B11: 1月 | C11: 湖北 | D11: 销售提升训 | E11: 《心态与成败》 | F11: 梁霞 | G11: 线下 | H11: 1212 | I11: app试卷考核 | J11: 46035 | K11: 黄建 | L11: 未签到 | M11: 01657 | N11: 湖北1部 | O11: 一星销售顾问 | P11: 45883 | Q11: 0 | R11: 0 | S11: 0
A12: 10 | B12: 1月 | C12: 西南总部 | D12: 销售提升训 | E12: 《心态与成败》 | F12: 梁霞 | G12: 线下 | H12: 1212 | I12: app试卷考核 | J12: 46035 | K12: 向巡 | L12: 未签到 | M12: 01634 | N12: 营业四部 | O12: 一星销售顾问 | P12: 45872 | Q12: 0 | R12: 0 | S12: 0
A13: 11 | B13: 1月 | C13: 西南总部 | D13: 销售提升训 | E13: 《心态与成败》 | F13: 梁霞 | G13: 线下 | H13: 1212 | I13: app试卷考核 | J13: 46035 | K13: 陈帅2 | L13: 未签到 | M13: 01488 | N13: 营业四部 | O13: 二星销售顾问 | P13: 45794 | Q13: 0 | R13: 0 | S13: 0
A14: 12 | B14: 1月 | C14: 陕西 | D14: 销售提升训 | E14: 《心态与成败》 | F14: 梁霞 | G14: 线下 | H14: 1212 | I14: app试卷考核 | J14: 46035 | K14: 涂正丽 | L14: 未签到 | M14: 01654 | N14: 陕西2部 | O14: 一星销售顾问 | P14: 45881 | Q14: 0 | R14: 0 | S14: 0
... A248: 246 | B248: 1月 | C248: 西南总部 | D248: 销售提升训 | E248: 《如何剖析客户心理》 | F248: 欧松林 | G248: 线下 | H248: 1212 | I248: app试卷考核 | J248: 46035 | K248: 向明镜 | L248: 已签到 | M248: 01265 | N248: 营业一部 | O248: 二星销售顾问 | P248: 45666 | Q248: 5 | R248: 5 | S248: 89
A249: 247 | B249: 1月 | C249: 山西 | D249: B岗培训 | E249: 《采购＋广告＋财务》 | F249: 李旭 | G249: 线上 | H249: 项目上 | I249: 学习地图考核 | J249: 46031 | K249: 赵龙 | L249: 已签到 | M249: 00996 | N249: 山西销售部 | O249: 三星销售顾问 | P249: 45502 | Q249: 5 | R249: 5 | S249: 0
A250: 248 | B250: 1月 | C250: 西南总部 | D250: B岗培训 | E250: 《采购＋广告＋财务》 | F250: 李旭 | G250: 线上 | H250: 项目上 | I250: 学习地图考核 | J250: 46031 | K250: 扈岭楠 | L250: 已签到 | M250: 00798 | N250: 营业三部 | O250: 一星销售顾问 | P250: 45269 | Q250: 5 | R250: 5 | S250: 0
A251: 249 | B251: 1月 | C251: 山东 | D251: B岗培训 | E251: 《采购＋广告＋财务》 | F251: 李旭 | G251: 线上 | H251: 项目上 | I251: 学习地图考核 | J251: 46031 | K251: 周涛 | L251: 已签到 | M251: 00869 | N251: 山东销售部 | O251: B岗经理 | P251: 45400 | Q251: 5 | R251: 5 | S251: 0
A252: 250 | B252: 1月 | C252: 西南总部 | D252: B岗培训 | E252: 《采购＋广告＋财务》 | F252: 蒋明霞 | G252: 线上 | H252: 项目上 | I252: 学习地图考核 | J252: 46031 | K252: 李海艳 | L252: 已签到 | M252: 01344 | N252: 营业三部 | O252: 二星销售顾问 | P252: 45706 | Q252: 5 | R252: 5 | S252: 0
A253: 251 | B253: 1月 | C253: 湖南 | D253: B岗培训 | E253: 《采购＋广告＋财务》 | F253: 蒋明霞 | G253: 线上 | H253: 项目上 | I253: 学习地图考核 | J253: 46031 | K253: 罗敏 | L253: 已签到 | M253: 00134 | N253: 湖南销售部 | O253: B岗经理 | P253: 44351 | Q253: 0 | R253: 0 | S253: 0
A254: 252 | B254: 1月 | C254: 西南总部 | D254: B岗培训 | E254: 《采购＋广告＋财务》 | F254: 蒋明霞 | G254: 线上 | H254: 项目上 | I254: 学习地图考核 | J254: 46031 | K254: 张圣梁 | L254: 已签到 | M254: 01047 | N254: 营业一部 | O254: B岗经理 | P254: 45545 | Q254: 0 | R254: 0 | S254: 0
A255: 253 | B255: 1月 | C255: 西南总部 | D255: B岗培训 | E255: 《采购＋广告＋财务》 | F255: 蒋明霞 | G255: 线上 | H255: 项目上 | I255: 学习地图考核 | J255: 46031 | K255: 郑雄 | L255: 已签到 | M255: 01456 | N255: 营业六部 | O255: B岗经理 | P255: 45763 | Q255: 0 | R255: 0 | S255: 0
A256: 254 | B256: 1月 | C256: 湖南 | D256: B岗培训 | E256: 《采购＋广告＋财务》 | F256: 蒋明霞 | G256: 线上 | H256: 项目上 | I256: 学习地图考核 | J256: 46031 | K256: 夏富杨 | L256: 已签到 | M256: 01317 | N256: 湖南销售部 | O256: 二星销售顾问 | P256: 45699 | Q256: 5 | R256: 5 | S256: 0
A257: 255 | B257: 1月 | C257: 西南总部 | D257: B岗培训 | E257: 《采购＋广告＋财务》 | F257: 蒋明霞 | G257: 线上 | H257: 项目上 | I257: 学习地图考核 | J257: 46031 | K257: 张萍2 | L257: 已签到 | M257: 01257 | N257: 营业五部 | O257: B岗经理 | P257: 45661 | Q257: 0 | R257: 0 | S257: 0
A258: 256 | B258: 1月 | C258: 西南总部 | D258: B岗培训 | E258: 《采购＋广告＋财务》 | F258: 蒋明霞 | G258: 线上 | H258: 项目上 | I258: 学习地图考核 | J258: 46031 | K258: 张萍 | L258: 已签到 | M258: 01166 | N258: 营业五部 | O258: 三星销售顾问 | P258: 45604 | Q258: 5 | R258: 5 | S258: 0
A259: 257 | B259: 1月 | C259: 西南总部 | D259: B岗培训 | E259: 《采购＋广告＋财务》 | F259: 李芙蓉 | G259: 线上 | H259: 项目上 | I259: 学习地图考核 | J259: 46031 | K259: 周远芮 | L259: 已签到 | M259: 01284 | N259: 营业五部 | O259: B岗经理 | P259: 45698 | Q259: 5 | R259: 5 | S259: 0
A260: 258 | B260: 1月 | C260: 西南总部 | D260: B岗培训 | E260: 《采购＋广告＋财务》 | F260: 李芙蓉 | G260: 线上 | H260: 项目上 | I260: 学习地图考核 | J260: 46031 | K260: 陶再阳 | L260: 已签到 | M260: 01271 | N260: 营业三部 | O260: B岗经理 | P260: 45669 | Q260: 5 | R260: 5 | S260: 0
... A268: 266 | B268: 1月 | C268: 陕西 | D268: B岗培训 | E268: 《采购＋广告＋财务》 | F268: 李芙蓉 | G268: 线上 | H268: 项目上 | I268: 学习地图考核 | J268: 46031 | K268: 马少波 | L268: 已签到 | M268: 01148 | N268: 陕西2部 | O268: 三星销售顾问 | P268: 45599 | Q268: 5 | R268: 5 | S268: 0
A269: 267 | B269: 1月 | C269: 山东 | D269: B岗培训 | E269: 《项目带看管理》 | F269: 刘盼 | G269: 线下 | H269: 1212 | I269: 学习地图考核 | J269: 46037 | K269: 周涛 | L269: 已签到 | M269: 00869 | N269: 山东销售部 | O269: B岗经理 | P269: 45400 | Q269: 5 | R269: 5 | S269: 0
A270: 268 | B270: 1月 | C270: 西南总部 | D270: B岗培训 | E270: 《项目带看管理》 | F270: 刘盼 | G270: 线下 | H270: 1212 | I270: 学习地图考核 | J270: 46037 | K270: 郑雄 | L270: 已签到 | M270: 01456 | N270: 营业六部 | O270: B岗经理 | P270: 45763 | Q270: 5 | R270: 5 | S270: 0
A271: 269 | B271: 1月 | C271: 西南总部 | D271: B岗培训 | E271: 《项目带看管理》 | F271: 刘盼 | G271: 线下 | H271: 1212 | I271: 学习地图考核 | J271: 46037 | K271: 张圣梁 | L271: 已签到 | M271: 01047 | N271: 营业一部 | O271: B岗经理 | P271: 45545 | Q271: 5 | R271: 5 | S271: 0
A272: 270 | B272: 1月 | C272: 西南总部 | D272: B岗培训 | E272: 《项目带看管理》 | F272: 刘盼 | G272: 线下 | H272: 1212 | I272: 学习地图考核 | J272: 46037 | K272: 陶再阳 | L272: 已签到 | M272: 01271 | N272: 营业三部 | O272: B岗经理 | P272: 45669 | Q272: 5 | R272: 5 | S272: 0
A273: 271 | B273: 1月 | C273: 湖南 | D273: B岗培训 | E273: 《项目带看管理》 | F273: 刘盼 | G273: 线下 | H273: 1212 | I273: 学习地图考核 | J273: 46037 | K273: 罗敏 | L273: 已签到 | M273: 00134 | N273: 湖南销售部 | O273: B岗经理 | P273: 44351 | Q273: 0 | R273: 0 | S273: 0
A274: 272 | B274: 1月 | C274: 西南总部 | D274: B岗培训 | E274: 《项目带看管理》 | F274: 刘盼 | G274: 线下 | H274: 1212 | I274: 学习地图考核 | J274: 46037 | K274: 李海艳 | L274: 已签到 | M274: 01344 | N274: 营业三部 | O274: 二星销售顾问 | P274: 45706 | Q274: 5 | R274: 5 | S274: 0
A275: 273 | B275: 1月 | C275: 山西 | D275: B岗培训 | E275: 《项目带看管理》 | F275: 刘盼 | G275: 线下 | H275: 1212 | I275: 学习地图考核 | J275: 46037 | K275: 赵龙 | L275: 已签到 | M275: 00996 | N275: 山西销售部 | O275: 三星销售顾问 | P275: 45502 | Q275: 5 | R275: 5 | S275: 0
A276: 274 | B276: 1月 | C276: 西南总部 | D276: B岗培训 | E276: 《项目带看管理》 | F276: 刘盼 | G276: 线下 | H276: 1212 | I276: 学习地图考核 | J276: 46037 | K276: 谢敏 | L276: 已签到 | M276: 00349 | N276: 营业五部 | O276: 三星实习经理 | P276: 44725 | Q276: 0 | R276: 0 | S276: 0
A277: 275 | B277: 1月 | C277: 西南总部 | D277: B岗培训 | E277: 《项目带看管理》 | F277: 刘盼 | G277: 线下 | H277: 1212 | I277: 学习地图考核 | J277: 46037 | K277: 张萍2 | L277: 已签到 | M277: 01257 | N277: 营业五部 | O277: B岗经理 | P277: 45661 | Q277: 0 | R277: 0 | S277: 0
A278: 276 | B278: 1月 | C278: 西南总部 | D278: B岗培训 | E278: 《项目带看管理》 | F278: 刘盼 | G278: 线下 | H278: 1212 | I278: 学习地图考核 | J278: 46037 | K278: 周远芮 | L278: 已签到 | M278: 01284 | N278: 营业五部 | O278: B岗经理 | P278: 45698 | Q278: 5 | R278: 5 | S278: 0
A279: 277 | B279: 1月 | C279: 湖北 | D279: B岗培训 | E279: 《项目带看管理》 | F279: 刘盼 | G279: 线下 | H279: 1212 | I279: 学习地图考核 | J279: 46037 | K279: 阮阳 | L279: 已签到 | M279: 01239 | N279: 湖北1部 | O279: 三星销售顾问 | P279: 45649 | Q279: 5 | R279: 5 | S279: 0
A280: 278 | B280: 1月 | C280: 山东 | D280: B岗培训 | E280: 《项目带看管理》 | F280: 刘盼 | G280: 线下 | H280: 1212 | I280: 学习地图考核 | J280: 46037 | K280: 吴江平 | L280: 已签到 | M280: 00898 | N280: 山东销售部 | O280: B岗经理 | P280: 45427 | Q280: 5 | R280: 5 | S280: 0
...

Sheet 《营业部》维度的参训率
A1: 《营业部》维度的参训率（1-3月）
A2: 序号 | B2: 月份 | C2: 城市 | D2: 营业部 | E2: 部长姓名 | F2: 课程类型 | G2: 应参训人次 | H2: 实际参训人次 | I2: 参训率
A3: 1 | B3: 1月 | C3: 西南总部 | D3: 营业五部 | E3: 叶鑫 | F3: 销售新人入职培训 | G3: =COUNTIFS('2026年度培训主表'!B:B,B3,'2026年度培训主表'!C:C,C3,'2026年度培训主表'!N:N,D3,'2026年度培训主表'!D:D,F3) -> 32 | H3: =COUNTIFS('2026年度培训主表'!B:B,B3,'2026年度培训主表'!C:C,C3,'2026年度培训主表'!N:N,D3,'2026年度培训主表'!D:D,F3,'2026年度培训主表'!L:L,"已签到") -> 0 | I3: =H3/G3 -> 0
A4: 2 | B4: 1月 | C4: 湖南 | D4: 湖南销售部 | E4: 刘进 | F4: 销售新人入职培训 | G4: =COUNTIFS('2026年度培训主表'!B:B,B4,'2026年度培训主表'!C:C,C4,'2026年度培训主表'!N:N,D4,'2026年度培训主表'!D:D,F4) -> 24 | H4: =COUNTIFS('2026年度培训主表'!B:B,B4,'2026年度培训主表'!C:C,C4,'2026年度培训主表'!N:N,D4,'2026年度培训主表'!D:D,F4,'2026年度培训主表'!L:L,"已签到") -> 12 | I4: =H4/G4 -> 0.5
A5: 3 | B5: 1月 | C5: 陕西 | D5: 陕西2部 | E5: 李耀 | F5: 销售新人入职培训 | G5: =COUNTIFS('2026年度培训主表'!B:B,B5,'2026年度培训主表'!C:C,C5,'2026年度培训主表'!N:N,D5,'2026年度培训主表'!D:D,F5) -> 16 | H5: =COUNTIFS('2026年度培训主表'!B:B,B5,'2026年度培训主表'!C:C,C5,'2026年度培训主表'!N:N,D5,'2026年度培训主表'!D:D,F5,'2026年度培训主表'!L:L,"已签到") -> 16 | I5: =H5/G5 -> 1
A6: 4 | B6: 1月 | C6: 西南总部 | D6: 营业六部 | E6: 毛富林 | F6: 销售新人入职培训 | G6: =COUNTIFS('2026年度培训主表'!B:B,B6,'2026年度培训主表'!C:C,C6,'2026年度培训主表'!N:N,D6,'2026年度培训主表'!D:D,F6) -> 29 | H6: =COUNTIFS('2026年度培训主表'!B:B,B6,'2026年度培训主表'!C:C,C6,'2026年度培训主表'!N:N,D6,'2026年度培训主表'!D:D,F6,'2026年度培训主表'!L:L,"已签到") -> 0 | I6: =H6/G6 -> 0
A7: 5 | B7: 1月 | C7: 西南总部 | D7: 营业三部 | E7: 周吉双 | F7: 销售新人入职培训 | G7: =COUNTIFS('2026年度培训主表'!B:B,B7,'2026年度培训主表'!C:C,C7,'2026年度培训主表'!N:N,D7,'2026年度培训主表'!D:D,F7) -> 28 | H7: =COUNTIFS('2026年度培训主表'!B:B,B7,'2026年度培训主表'!C:C,C7,'2026年度培训主表'!N:N,D7,'2026年度培训主表'!D:D,F7,'2026年度培训主表'!L:L,"已签到") -> 8 | I7: =H7/G7 -> 0.28571429
A8: 6 | B8: 1月 | C8: 西南总部 | D8: 营业一部 | E8: 雷小金 | F8: 销售新人入职培训 | G8: =COUNTIFS('2026年度培训主表'!B:B,B8,'2026年度培训主表'!C:C,C8,'2026年度培训主表'!N:N,D8,'2026年度培训主表'!D:D,F8) -> 28 | H8: =COUNTIFS('2026年度培训主表'!B:B,B8,'2026年度培训主表'!C:C,C8,'2026年度培训主表'!N:N,D8,'2026年度培训主表'!D:D,F8,'2026年度培训主表'!L:L,"已签到") -> 16 | I8: =H8/G8 -> 0.57142857
A9: 7 | B9: 1月 | C9: 河南 | D9: 河南销售部 | E9: 毛孝树 | F9: 销售新人入职培训 | G9: =COUNTIFS('2026年度培训主表'!B:B,B9,'2026年度培训主表'!C:C,C9,'2026年度培训主表'!N:N,D9,'2026年度培训主表'!D:D,F9) -> 24 | H9: =COUNTIFS('2026年度培训主表'!B:B,B9,'2026年度培训主表'!C:C,C9,'2026年度培训主表'!N:N,D9,'2026年度培训主表'!D:D,F9,'2026年度培训主表'!L:L,"已签到") -> 20 | I9: =H9/G9 -> 0.83333333
A10: 8 | B10: 1月 | C10: 西南总部 | D10: 营业二部 | E10: 柏刚 | F10: 销售新人入职培训 | G10: =COUNTIFS('2026年度培训主表'!B:B,B10,'2026年度培训主表'!C:C,C10,'2026年度培训主表'!N:N,D10,'2026年度培训主表'!D:D,F10) -> 24 | H10: =COUNTIFS('2026年度培训主表'!B:B,B10,'2026年度培训主表'!C:C,C10,'2026年度培训主表'!N:N,D10,'2026年度培训主表'!D:D,F10,'2026年度培训主表'!L:L,"已签到") -> 8 | I10: =H10/G10 -> 0.33333333
A11: 9 | B11: 1月 | C11: 西南总部 | D11: 营业七部 | E11: 程新浩 | F11: 销售新人入职培训 | G11: =COUNTIFS('2026年度培训主表'!B:B,B11,'2026年度培训主表'!C:C,C11,'2026年度培训主表'!N:N,D11,'2026年度培训主表'!D:D,F11) -> 28 | H11: =COUNTIFS('2026年度培训主表'!B:B,B11,'2026年度培训主表'!C:C,C11,'2026年度培训主表'!N:N,D11,'2026年度培训主表'!D:D,F11,'2026年度培训主表'!L:L,"已签到") -> 12 | I11: =H11/G11 -> 0.42857143
A12: 10 | B12: 1月 | C12: 湖北 | D12: 湖北2部 | E12: 陈晓辉 | F12: 销售新人入职培训 | G12: =COUNTIFS('2026年度培训主表'!B:B,B12,'2026年度培训主表'!C:C,C12,'2026年度培训主表'!N:N,D12,'2026年度培训主表'!D:D,F12) -> 4 | H12: =COUNTIFS('2026年度培训主表'!B:B,B12,'2026年度培训主表'!C:C,C12,'2026年度培训主表'!N:N,D12,'2026年度培训主表'!D:D,F12,'2026年度培训主表'!L:L,"已签到") -> 4 | I12: =H12/G12 -> 1
A13: 11 | B13: 1月 | C13: 甘肃 | D13: 甘肃销售部 | E13: 李耀 | F13: 销售新人入职培训 | G13: =COUNTIFS('2026年度培训主表'!B:B,B13,'2026年度培训主表'!C:C,C13,'2026年度培训主表'!N:N,D13,'2026年度培训主表'!D:D,F13) -> 4 | H13: =COUNTIFS('2026年度培训主表'!B:B,B13,'2026年度培训主表'!C:C,C13,'2026年度培训主表'!N:N,D13,'2026年度培训主表'!D:D,F13,'2026年度培训主表'!L:L,"已签到") -> 4 | I13: =H13/G13 -> 1
A14: 12 | B14: 1月 | C14: 山东 | D14: 山东销售部 | E14: 李丹 | F14: 销售新人入职培训 | G14: =COUNTIFS('2026年度培训主表'!B:B,B14,'2026年度培训主表'!C:C,C14,'2026年度培训主表'!N:N,D14,'2026年度培训主表'!D:D,F14) -> 8 | H14: =COUNTIFS('2026年度培训主表'!B:B,B14,'2026年度培训主表'!C:C,C14,'2026年度培训主表'!N:N,D14,'2026年度培训主表'!D:D,F14,'2026年度培训主表'!L:L,"已签到") -> 8 | I14: =H14/G14 -> 1
... A64: 62 | B64: 1月 | C64: 河北 | D64: 河北销售部 | E64: 李港一 | F64: 销售经理培训 | G64: =COUNTIFS('2026年度培训主表'!B:B,B64,'2026年度培训主表'!C:C,C64,'2026年度培训主表'!N:N,D64,'2026年度培训主表'!D:D,F64) -> 2 | H64: =COUNTIFS('2026年度培训主表'!B:B,B64,'2026年度培训主表'!C:C,C64,'2026年度培训主表'!N:N,D64,'2026年度培训主表'!D:D,F64,'2026年度培训主表'!L:L,"已签到") -> 2 | I64: =H64/G64 -> 1
A65: 63 | B65: 2月 | C65: 西南总部 | D65: 营业五部 | E65: 叶鑫 | F65: 讲师《TTT》培训 | G65: =COUNTIFS('2026年度培训主表'!B:B,B65,'2026年度培训主表'!C:C,C65,'2026年度培训主表'!N:N,D65,'2026年度培训主表'!D:D,F65) -> 4 | H65: =COUNTIFS('2026年度培训主表'!B:B,B65,'2026年度培训主表'!N:N,D65,'2026年度培训主表'!L:L,"已签到") -> 4 | I65: =H65/G65 -> 1
A66: 64 | B66: 2月 | C66: 湖南 | D66: 湖南销售部 | E66: 刘进 | F66: 讲师《TTT》培训 | G66: =COUNTIFS('2026年度培训主表'!B:B,B66,'2026年度培训主表'!C:C,C66,'2026年度培训主表'!N:N,D66,'2026年度培训主表'!D:D,F66) -> 6 | H66: =COUNTIFS('2026年度培训主表'!B:B,B66,'2026年度培训主表'!N:N,D66,'2026年度培训主表'!L:L,"已签到") -> 6 | I66: =H66/G66 -> 1
A67: 65 | B67: 2月 | C67: 陕西 | D67: 陕西2部 | E67: 李耀 | F67: 讲师《TTT》培训 | G67: =COUNTIFS('2026年度培训主表'!B:B,B67,'2026年度培训主表'!C:C,C67,'2026年度培训主表'!N:N,D67,'2026年度培训主表'!D:D,F67) -> 2 | H67: =COUNTIFS('2026年度培训主表'!B:B,B67,'2026年度培训主表'!N:N,D67,'2026年度培训主表'!L:L,"已签到") -> 2 | I67: =H67/G67 -> 1
A68: 66 | B68: 2月 | C68: 西南总部 | D68: 营业六部 | E68: 毛富林 | F68: 讲师《TTT》培训 | G68: =COUNTIFS('2026年度培训主表'!B:B,B68,'2026年度培训主表'!C:C,C68,'2026年度培训主表'!N:N,D68,'2026年度培训主表'!D:D,F68) -> 2 | H68: =COUNTIFS('2026年度培训主表'!B:B,B68,'2026年度培训主表'!N:N,D68,'2026年度培训主表'!L:L,"已签到") -> 2 | I68: =H68/G68 -> 1
A69: 67 | B69: 2月 | C69: 西南总部 | D69: 营业三部 | E69: 周吉双 | F69: 讲师《TTT》培训 | G69: =COUNTIFS('2026年度培训主表'!B:B,B69,'2026年度培训主表'!C:C,C69,'2026年度培训主表'!N:N,D69,'2026年度培训主表'!D:D,F69) -> 4 | H69: =COUNTIFS('2026年度培训主表'!B:B,B69,'2026年度培训主表'!N:N,D69,'2026年度培训主表'!L:L,"已签到") -> 4 | I69: =H69/G69 -> 1
A70: 68 | B70: 2月 | C70: 西南总部 | D70: 营业一部 | E70: 雷小金 | F70: 讲师《TTT》培训 | G70: =COUNTIFS('2026年度培训主表'!B:B,B70,'2026年度培训主表'!C:C,C70,'2026年度培训主表'!N:N,D70,'2026年度培训主表'!D:D,F70) -> 2 | H70: =COUNTIFS('2026年度培训主表'!B:B,B70,'2026年度培训主表'!N:N,D70,'2026年度培训主表'!L:L,"已签到") -> 2 | I70: =H70/G70 -> 1
A71: 69 | B71: 2月 | C71: 河南 | D71: 河南销售部 | E71: 毛孝树 | F71: 讲师《TTT》培训 | G71: =COUNTIFS('2026年度培训主表'!B:B,B71,'2026年度培训主表'!C:C,C71,'2026年度培训主表'!N:N,D71,'2026年度培训主表'!D:D,F71) -> 2 | H71: =COUNTIFS('2026年度培训主表'!B:B,B71,'2026年度培训主表'!N:N,D71,'2026年度培训主表'!L:L,"已签到") -> 2 | I71: =H71/G71 -> 1
A72: 70 | B72: 2月 | C72: 西南总部 | D72: 营业二部 | E72: 柏刚 | F72: 讲师《TTT》培训 | G72: =COUNTIFS('2026年度培训主表'!B:B,B72,'2026年度培训主表'!C:C,C72,'2026年度培训主表'!N:N,D72,'2026年度培训主表'!D:D,F72) -> 4 | H72: =COUNTIFS('2026年度培训主表'!B:B,B72,'2026年度培训主表'!N:N,D72,'2026年度培训主表'!L:L,"已签到") -> 4 | I72: =H72/G72 -> 1
A73: 71 | B73: 2月 | C73: 西南总部 | D73: 营业七部 | E73: 程新浩 | F73: 讲师《TTT》培训 | G73: =COUNTIFS('2026年度培训主表'!B:B,B73,'2026年度培训主表'!C:C,C73,'2026年度培训主表'!N:N,D73,'2026年度培训主表'!D:D,F73) -> 2 | H73: =COUNTIFS('2026年度培训主表'!B:B,B73,'2026年度培训主表'!N:N,D73,'2026年度培训主表'!L:L,"已签到") -> 2 | I73: =H73/G73 -> 1
A74: 72 | B74: 2月 | C74: 湖北 | D74: 湖北2部 | E74: 陈晓辉 | F74: 讲师《TTT》培训 | G74: =COUNTIFS('2026年度培训主表'!B:B,B74,'2026年度培训主表'!C:C,C74,'2026年度培训主表'!N:N,D74,'2026年度培训主表'!D:D,F74) -> 2 | H74: =COUNTIFS('2026年度培训主表'!B:B,B74,'2026年度培训主表'!N:N,D74,'2026年度培训主表'!L:L,"已签到") -> 2 | I74: =H74/G74 -> 1
A75: 74 | B75: 2月 | C75: 山东 | D75: 山东销售部 | E75: 李丹 | F75: 讲师《TTT》培训 | G75: =COUNTIFS('2026年度培训主表'!B:B,B75,'2026年度培训主表'!C:C,C75,'2026年度培训主表'!N:N,D75,'2026年度培训主表'!D:D,F75) -> 6 | H75: =COUNTIFS('2026年度培训主表'!B:B,B75,'2026年度培训主表'!N:N,D75,'2026年度培训主表'!L:L,"已签到") -> 6 | I75: =H75/G75 -> 1
A76: 76 | B76: 2月 | C76: 湖北 | D76: 湖北1部 | E76: 林浩 | F76: 讲师《TTT》培训 | G76: =COUNTIFS('2026年度培训主表'!B:B,B76,'2026年度培训主表'!C:C,C76,'2026年度培训主表'!N:N,D76,'2026年度培训主表'!D:D,F76) -> 4 | H76: =COUNTIFS('2026年度培训主表'!B:B,B76,'2026年度培训主表'!N:N,D76,'2026年度培训主表'!L:L,"已签到") -> 4 | I76: =H76/G76 -> 1
... A95: 96 | B95: 2月 | C95: 河北 | D95: 河北拓展部 | E95: 张冀 | F95: 讲师《TTT》培训 | G95: =COUNTIFS('2026年度培训主表'!B:B,B95,'2026年度培训主表'!C:C,C95,'2026年度培训主表'!N:N,D95,'2026年度培训主表'!D:D,F95) -> 4 | H95: =COUNTIFS('2026年度培训主表'!B:B,B95,'2026年度培训主表'!N:N,D95,'2026年度培训主表'!L:L,"已签到") -> 4 | I95: =H95/G95 -> 1
A96: 97 | B96: 3月 | C96: 西南总部 | D96: 营业一部 | E96: 雷小金 | F96: 销售新人入职培训 | G96: =COUNTIFS('2026年度培训主表'!B:B,B96,'2026年度培训主表'!D:D,F96,'2026年度培训主表'!N:N,D96) -> 52 | H96: =COUNTIFS('2026年度培训主表'!B:B,B96,'2026年度培训主表'!D:D,F96,'2026年度培训主表'!N:N,D96,'2026年度培训主表'!L:L,"已签到") -> 36 | I96: =H96/G96 -> 0.69230769
A97: 98 | B97: 3月 | C97: 西南总部 | D97: 营业二部 | E97: 柏刚 | F97: 销售新人入职培训 | G97: =COUNTIFS('2026年度培训主表'!B:B,B97,'2026年度培训主表'!D:D,F97,'2026年度培训主表'!N:N,D97) -> 20 | H97: =COUNTIFS('2026年度培训主表'!B:B,B97,'2026年度培训主表'!D:D,F97,'2026年度培训主表'!N:N,D97,'2026年度培训主表'!L:L,"已签到") -> 0 | I97: =H97/G97 -> 0
A98: 99 | B98: 3月 | C98: 西南总部 | D98: 营业三部 | E98: 周吉双 | F98: 销售新人入职培训 | G98: =COUNTIFS('2026年度培训主表'!B:B,B98,'2026年度培训主表'!D:D,F98,'2026年度培训主表'!N:N,D98) -> 12 | H98: =COUNTIFS('2026年度培训主表'!B:B,B98,'2026年度培训主表'!D:D,F98,'2026年度培训主表'!N:N,D98,'2026年度培训主表'!L:L,"已签到") -> 8 | I98: =H98/G98 -> 0.66666667
A99: 100 | B99: 3月 | C99: 西南总部 | D99: 营业四部 | E99: 刘亮 | F99: 销售新人入职培训 | G99: =COUNTIFS('2026年度培训主表'!B:B,B99,'2026年度培训主表'!D:D,F99,'2026年度培训主表'!N:N,D99) -> 16 | H99: =COUNTIFS('2026年度培训主表'!B:B,B99,'2026年度培训主表'!D:D,F99,'2026年度培训主表'!N:N,D99,'2026年度培训主表'!L:L,"已签到") -> 0 | I99: =H99/G99 -> 0
A100: 101 | B100: 3月 | C100: 西南总部 | D100: 营业五部 | E100: 叶鑫 | F100: 销售新人入职培训 | G100: =COUNTIFS('2026年度培训主表'!B:B,B100,'2026年度培训主表'!D:D,F100,'2026年度培训主表'!N:N,D100) -> 44 | H100: =COUNTIFS('2026年度培训主表'!B:B,B100,'2026年度培训主表'!D:D,F100,'2026年度培训主表'!N:N,D100,'2026年度培训主表'!L:L,"已签到") -> 4 | I100: =H100/G100 -> 0.090909091
A101: 102 | B101: 3月 | C101: 西南总部 | D101: 营业六部 | E101: 毛富林 | F101: 销售新人入职培训 | G101: =COUNTIFS('2026年度培训主表'!B:B,B101,'2026年度培训主表'!D:D,F101,'2026年度培训主表'!N:N,D101) -> 40 | H101: =COUNTIFS('2026年度培训主表'!B:B,B101,'2026年度培训主表'!D:D,F101,'2026年度培训主表'!N:N,D101,'2026年度培训主表'!L:L,"已签到") -> 12 | I101: =H101/G101 -> 0.3
A102: 103 | B102: 3月 | C102: 西南总部 | D102: 营业七部 | E102: 程新浩 | F102: 销售新人入职培训 | G102: =COUNTIFS('2026年度培训主表'!B:B,B102,'2026年度培训主表'!D:D,F102,'2026年度培训主表'!N:N,D102) -> 36 | H102: =COUNTIFS('2026年度培训主表'!B:B,B102,'2026年度培训主表'!D:D,F102,'2026年度培训主表'!N:N,D102,'2026年度培训主表'!L:L,"已签到") -> 8 | I102: =H102/G102 -> 0.22222222
A103: 105 | B103: 3月 | C103: 河北 | D103: 河北销售部 | E103: 李港一 | F103: 销售新人入职培训 | G103: =COUNTIFS('2026年度培训主表'!B:B,B103,'2026年度培训主表'!D:D,F103,'2026年度培训主表'!N:N,D103) -> 16 | H103: =COUNTIFS('2026年度培训主表'!B:B,B103,'2026年度培训主表'!D:D,F103,'2026年度培训主表'!N:N,D103,'2026年度培训主表'!L:L,"已签到") -> 8 | I103: =H103/G103 -> 0.5
A104: 106 | B104: 3月 | C104: 河南 | D104: 河南销售部 | E104: 毛孝树 | F104: 销售新人入职培训 | G104: =COUNTIFS('2026年度培训主表'!B:B,B104,'2026年度培训主表'!D:D,F104,'2026年度培训主表'!N:N,D104) -> 12 | H104: =COUNTIFS('2026年度培训主表'!B:B,B104,'2026年度培训主表'!D:D,F104,'2026年度培训主表'!N:N,D104,'2026年度培训主表'!L:L,"已签到") -> 8 | I104: =H104/G104 -> 0.66666667
A105: 107 | B105: 3月 | C105: 湖北 | D105: 湖北1部 | E105: 林浩 | F105: 销售新人入职培训 | G105: =COUNTIFS('2026年度培训主表'!B:B,B105,'2026年度培训主表'!D:D,F105,'2026年度培训主表'!N:N,D105) -> 12 | H105: =COUNTIFS('2026年度培训主表'!B:B,B105,'2026年度培训主表'!D:D,F105,'2026年度培训主表'!N:N,D105,'2026年度培训主表'!L:L,"已签到") -> 8 | I105: =H105/G105 -> 0.66666667
A106: 108 | B106: 3月 | C106: 湖北 | D106: 湖北2部 | E106: 陈晓辉 | F106: 销售新人入职培训 | G106: =COUNTIFS('2026年度培训主表'!B:B,B106,'2026年度培训主表'!D:D,F106,'2026年度培训主表'!N:N,D106) -> 4 | H106: =COUNTIFS('2026年度培训主表'!B:B,B106,'2026年度培训主表'!D:D,F106,'2026年度培训主表'!N:N,D106,'2026年度培训主表'!L:L,"已签到") -> 4 | I106: =H106/G106 -> 1
A107: 109 | B107: 3月 | C107: 湖南 | D107: 湖南销售部 | E107: 刘进 | F107: 销售新人入职培训 | G107: =COUNTIFS('2026年度培训主表'!B:B,B107,'2026年度培训主表'!D:D,F107,'2026年度培训主表'!N:N,D107) -> 20 | H107: =COUNTIFS('2026年度培训主表'!B:B,B107,'2026年度培训主表'!D:D,F107,'2026年度培训主表'!N:N,D107,'2026年度培训主表'!L:L,"已签到") -> 16 | I107: =H107/G107 -> 0.8
...

Sheet 《分公司》维度的参训率
A1: 《分公司》维度的参训率（1-3月）
A2: 序号 | B2: 月份 | C2: 城市 | D2: 课程类型 | E2: 应参训人次 | F2: 实际参训人次 | G2: 参训率
A3: 1 | B3: 1月 | C3: 西南总部 | D3: 销售新人入职培训 | E3: =COUNTIFS('2026年度培训主表'!B:B,B3,'2026年度培训主表'!C:C,C3,'2026年度培训主表'!D:D,D3) -> 195 | F3: =COUNTIFS('2026年度培训主表'!B:B,B3,'2026年度培训主表'!C:C,C3,'2026年度培训主表'!D:D,D3,'2026年度培训主表'!L:L,"已签到") -> 53 | G3: =F3/E3 -> 0.27179487
A4: 2 | B4: 1月 | C4: 湖南 | D4: 销售新人入职培训 | E4: =COUNTIFS('2026年度培训主表'!B:B,B4,'2026年度培训主表'!C:C,C4,'2026年度培训主表'!D:D,D4) -> 24 | F4: =COUNTIFS('2026年度培训主表'!B:B,B4,'2026年度培训主表'!C:C,C4,'2026年度培训主表'!D:D,D4,'2026年度培训主表'!L:L,"已签到") -> 12 | G4: =F4/E4 -> 0.5
A5: 3 | B5: 1月 | C5: 陕西 | D5: 销售新人入职培训 | E5: =COUNTIFS('2026年度培训主表'!B:B,B5,'2026年度培训主表'!C:C,C5,'2026年度培训主表'!D:D,D5) -> 16 | F5: =COUNTIFS('2026年度培训主表'!B:B,B5,'2026年度培训主表'!C:C,C5,'2026年度培训主表'!D:D,D5,'2026年度培训主表'!L:L,"已签到") -> 16 | G5: =F5/E5 -> 1
A6: 4 | B6: 1月 | C6: 河南 | D6: 销售新人入职培训 | E6: =COUNTIFS('2026年度培训主表'!B:B,B6,'2026年度培训主表'!C:C,C6,'2026年度培训主表'!D:D,D6) -> 24 | F6: =COUNTIFS('2026年度培训主表'!B:B,B6,'2026年度培训主表'!C:C,C6,'2026年度培训主表'!D:D,D6,'2026年度培训主表'!L:L,"已签到") -> 20 | G6: =F6/E6 -> 0.83333333
A7: 5 | B7: 1月 | C7: 湖北 | D7: 销售新人入职培训 | E7: =COUNTIFS('2026年度培训主表'!B:B,B7,'2026年度培训主表'!C:C,C7,'2026年度培训主表'!D:D,D7) -> 12 | F7: =COUNTIFS('2026年度培训主表'!B:B,B7,'2026年度培训主表'!C:C,C7,'2026年度培训主表'!D:D,D7,'2026年度培训主表'!L:L,"已签到") -> 12 | G7: =F7/E7 -> 1
A8: 6 | B8: 1月 | C8: 甘肃 | D8: 销售新人入职培训 | E8: =COUNTIFS('2026年度培训主表'!B:B,B8,'2026年度培训主表'!C:C,C8,'2026年度培训主表'!D:D,D8) -> 4 | F8: =COUNTIFS('2026年度培训主表'!B:B,B8,'2026年度培训主表'!C:C,C8,'2026年度培训主表'!D:D,D8,'2026年度培训主表'!L:L,"已签到") -> 4 | G8: =F8/E8 -> 1
A9: 7 | B9: 1月 | C9: 山东 | D9: 销售新人入职培训 | E9: =COUNTIFS('2026年度培训主表'!B:B,B9,'2026年度培训主表'!C:C,C9,'2026年度培训主表'!D:D,D9) -> 8 | F9: =COUNTIFS('2026年度培训主表'!B:B,B9,'2026年度培训主表'!C:C,C9,'2026年度培训主表'!D:D,D9,'2026年度培训主表'!L:L,"已签到") -> 8 | G9: =F9/E9 -> 1
A10: 8 | B10: 1月 | C10: 内蒙古 | D10: 销售新人入职培训 | E10: =COUNTIFS('2026年度培训主表'!B:B,B10,'2026年度培训主表'!C:C,C10,'2026年度培训主表'!D:D,D10) -> 12 | F10: =COUNTIFS('2026年度培训主表'!B:B,B10,'2026年度培训主表'!C:C,C10,'2026年度培训主表'!D:D,D10,'2026年度培训主表'!L:L,"已签到") -> 12 | G10: =F10/E10 -> 1
A11: 9 | B11: 1月 | C11: 河北 | D11: 销售新人入职培训 | E11: =COUNTIFS('2026年度培训主表'!B:B,B11,'2026年度培训主表'!C:C,C11,'2026年度培训主表'!D:D,D11) -> 16 | F11: =COUNTIFS('2026年度培训主表'!B:B,B11,'2026年度培训主表'!C:C,C11,'2026年度培训主表'!D:D,D11,'2026年度培训主表'!L:L,"已签到") -> 12 | G11: =F11/E11 -> 0.75
A12: 10 | B12: 1月 | C12: 西南总部 | D12: 销售提升训 | E12: =COUNTIFS('2026年度培训主表'!B:B,B12,'2026年度培训主表'!C:C,C12,'2026年度培训主表'!D:D,D12) -> 163 | F12: =COUNTIFS('2026年度培训主表'!B:B,B12,'2026年度培训主表'!C:C,C12,'2026年度培训主表'!D:D,D12,'2026年度培训主表'!L:L,"已签到") -> 55 | G12: =F12/E12 -> 0.33742331
A13: 11 | B13: 1月 | C13: 陕西 | D13: 销售提升训 | E13: =COUNTIFS('2026年度培训主表'!B:B,B13,'2026年度培训主表'!C:C,C13,'2026年度培训主表'!D:D,D13) -> 12 | F13: =COUNTIFS('2026年度培训主表'!B:B,B13,'2026年度培训主表'!C:C,C13,'2026年度培训主表'!D:D,D13,'2026年度培训主表'!L:L,"已签到") -> 9 | G13: =F13/E13 -> 0.75
A14: 12 | B14: 1月 | C14: 湖北 | D14: 销售提升训 | E14: =COUNTIFS('2026年度培训主表'!B:B,B14,'2026年度培训主表'!C:C,C14,'2026年度培训主表'!D:D,D14) -> 14 | F14: =COUNTIFS('2026年度培训主表'!B:B,B14,'2026年度培训主表'!C:C,C14,'2026年度培训主表'!D:D,D14,'2026年度培训主表'!L:L,"已签到") -> 0 | G14: =F14/E14 -> 0
... A77: 85 | B77: 3月 | C77: 辽宁 | D77: 销售新人入职培训 | E77: =COUNTIFS('2026年度培训主表'!B:B,B77,'2026年度培训主表'!C:C,C77,'2026年度培训主表'!D:D,D77) -> 8 | F77: =COUNTIFS('2026年度培训主表'!B:B,B77,'2026年度培训主表'!C:C,C77,'2026年度培训主表'!D:D,D77,'2026年度培训主表'!L:L,"已签到") -> 8 | G77: =F77/E77 -> 1

Sheet 《课程名称》维度的参训明细（主表）
A1: 《课程名称》维度的参训明细（主表）1-3月
A2: 序号 | B2: 月份 | C2: 城市 | D2: 营业部 | E2: 直系上级 | F2: 应参训人姓名 | G2: 工号 | H2: 职级 | I2: 签到情况 | J2: 培训时间 | K2: 课程名称 | L2: 授课类型
A3: 1 | B3: 1月 | C3: 西南总部 | D3: 营业五部 | E3: 安芮内蒙古 | F3: 蒋婷 | G3: 01011 | H3: 一星销售顾问 | I3: 未签到 | J3: 46035 | K3: 《心态与成败》 | L3: 销售提升训
A4: 2 | B4: 1月 | C4: 西南总部 | D4: 营业五部 | E4: 安芮内蒙古 | F4: 孙智港 | G4: 01423 | H4: 一星销售顾问 | I4: 未签到 | J4: 46035 | K4: 《心态与成败》 | L4: 销售提升训
A5: 3 | B5: 1月 | C5: 西南总部 | D5: 营业五部 | E5: 安芮内蒙古 | F5: 李裕楷 | G5: 01412 | H5: 一星销售顾问 | I5: 未签到 | J5: 46035 | K5: 《心态与成败》 | L5: 销售提升训
A6: 4 | B6: 1月 | C6: 西南总部 | D6: 营业二部 | E6: 柏刚 | F6: 税小蓉 | G6: 01684 | H6: 一星销售顾问 | I6: 已签到 | J6: 46035 | K6: 《心态与成败》 | L6: 销售提升训
A7: 5 | B7: 1月 | C7: 陕西 | D7: 陕西2部 | E7: 李丝丝 | F7: 李松 | G7: 01689 | H7: 一星销售顾问 | I7: 已签到 | J7: 46035 | K7: 《心态与成败》 | L7: 销售提升训
A8: 6 | B8: 1月 | C8: 西南总部 | D8: 营业一部 | E8: 白世根 | F8: 先波 | G8: 01512 | H8: 二星销售顾问 | I8: 未签到 | J8: 46035 | K8: 《心态与成败》 | L8: 销售提升训
A9: 7 | B9: 1月 | C9: 西南总部 | D9: 营业七部 | E9: 陈彪 | F9: 田丰 | G9: 01500 | H9: 一星销售顾问 | I9: 未签到 | J9: 46035 | K9: 《心态与成败》 | L9: 销售提升训
A10: 8 | B10: 1月 | C10: 西南总部 | D10: 营业四部 | E10: 陈帅 | F10: 邓孝礼 | G10: 01621 | H10: 一星销售顾问 | I10: 已签到 | J10: 46035 | K10: 《心态与成败》 | L10: 销售提升训
A11: 9 | B11: 1月 | C11: 湖北 | D11: 湖北1部 | E11: 张宗铭湖北 | F11: 黄建 | G11: 01657 | H11: 一星销售顾问 | I11: 未签到 | J11: 46035 | K11: 《心态与成败》 | L11: 销售提升训
A12: 10 | B12: 1月 | C12: 西南总部 | D12: 营业四部 | E12: 陈嘉文 | F12: 向巡 | G12: 01634 | H12: 一星销售顾问 | I12: 未签到 | J12: 46035 | K12: 《心态与成败》 | L12: 销售提升训
A13: 11 | B13: 1月 | C13: 西南总部 | D13: 营业四部 | E13: 陈嘉文 | F13: 陈帅2 | G13: 01488 | H13: 二星销售顾问 | I13: 未签到 | J13: 46035 | K13: 《心态与成败》 | L13: 销售提升训
A14: 12 | B14: 1月 | C14: 陕西 | D14: 陕西2部 | E14: 冀敏 | F14: 涂正丽 | G14: 01654 | H14: 一星销售顾问 | I14: 未签到 | J14: 46035 | K14: 《心态与成败》 | L14: 销售提升训
... A761: 759 | B761: 1月 | C761: 西南总部 | D761: 营业一部 | E761: 白世根 | F761: 李青松 | G761: 01821 | H761: 实习销售 | I761: 未签到 | J761: 46051 | K761: 《走进蜂族科技》 | L761: 销售新人入职培训
A762: 760 | B762: 2月 | C762: =VLOOKUP(F762,[4]在职!$A:$E,5,0) -> 安徽 | D762: 安徽拓展部 | E762: =VLOOKUP(F762,[4]在职!$A:$M,13,0) -> 黄芳 | F762: 许钊 | G762: =VLOOKUP(F762,[4]在职!$A:$B,2,0) -> 00032 | H762: =VLOOKUP(F762,[4]在职!$A:$I,9,0) -> 分公司总经理 | I762: 已签到 | J762: 46077 | K762: 《讲师TTT培训》 | L762: 《讲师TTT培训》
A763: 761 | B763: 2月 | C763: =VLOOKUP(F763,[4]在职!$A:$E,5,0) -> 安徽 | D763: 安徽拓展部 | E763: =VLOOKUP(F763,[4]在职!$A:$M,13,0) -> 黄芳 | F763: 许钊 | G763: =VLOOKUP(F763,[4]在职!$A:$B,2,0) -> 00032 | H763: =VLOOKUP(F763,[4]在职!$A:$I,9,0) -> 分公司总经理 | I763: 已签到 | J763: 46078 | K763: 《讲师TTT培训》 | L763: 《讲师TTT培训》
A764: 762 | B764: 2月 | C764: =VLOOKUP(F764,[4]在职!$A:$E,5,0) -> 西南总部 | D764: =VLOOKUP(F764,[4]在职!$A:$G,7,0) -> 川北 | E764: =VLOOKUP(F764,[4]在职!$A:$M,13,0) -> 刘文宇 | F764: 蒋婉萍 | G764: =VLOOKUP(F764,[4]在职!$A:$B,2,0) -> 00745 | H764: =VLOOKUP(F764,[4]在职!$A:$I,9,0) -> 区域拓展总监 | I764: 已签到 | J764: 46077 | K764: 《讲师TTT培训》 | L764: 《讲师TTT培训》
A765: 763 | B765: 2月 | C765: =VLOOKUP(F765,[4]在职!$A:$E,5,0) -> 西南总部 | D765: =VLOOKUP(F765,[4]在职!$A:$G,7,0) -> 川北 | E765: =VLOOKUP(F765,[4]在职!$A:$M,13,0) -> 刘文宇 | F765: 蒋婉萍 | G765: =VLOOKUP(F765,[4]在职!$A:$B,2,0) -> 00745 | H765: =VLOOKUP(F765,[4]在职!$A:$I,9,0) -> 区域拓展总监 | I765: 已签到 | J765: 46078 | K765: 《讲师TTT培训》 | L765: 《讲师TTT培训》
A766: 764 | B766: 2月 | C766: =VLOOKUP(F766,[4]在职!$A:$E,5,0) -> 西南总部 | D766: =VLOOKUP(F766,[4]在职!$A:$G,7,0) -> 川东 | E766: =VLOOKUP(F766,[4]在职!$A:$M,13,0) -> 刘文宇 | F766: 刘超 | G766: =VLOOKUP(F766,[4]在职!$A:$B,2,0) -> 00029 | H766: =VLOOKUP(F766,[4]在职!$A:$I,9,0) -> 区域拓展总监 | I766: 已签到 | J766: 46077 | K766: 《讲师TTT培训》 | L766: 《讲师TTT培训》
A767: 765 | B767: 2月 | C767: =VLOOKUP(F767,[4]在职!$A:$E,5,0) -> 西南总部 | D767: =VLOOKUP(F767,[4]在职!$A:$G,7,0) -> 川东 | E767: =VLOOKUP(F767,[4]在职!$A:$M,13,0) -> 刘超 | F767: 向高涵 | G767: =VLOOKUP(F767,[4]在职!$A:$B,2,0) -> 00590 | H767: =VLOOKUP(F767,[4]在职!$A:$I,9,0) -> 二星拓展专员 | I767: 已签到 | J767: 46077 | K767: 《讲师TTT培训》 | L767: 《讲师TTT培训》
A768: 766 | B768: 2月 | C768: =VLOOKUP(F768,[4]在职!$A:$E,5,0) -> 西南总部 | D768: =VLOOKUP(F768,[4]在职!$A:$G,7,0) -> 川东 | E768: =VLOOKUP(F768,[4]在职!$A:$M,13,0) -> 刘文宇 | F768: 刘超 | G768: =VLOOKUP(F768,[4]在职!$A:$B,2,0) -> 00029 | H768: =VLOOKUP(F768,[4]在职!$A:$I,9,0) -> 区域拓展总监 | I768: 已签到 | J768: 46078 | K768: 《讲师TTT培训》 | L768: 《讲师TTT培训》
A769: 767 | B769: 2月 | C769: =VLOOKUP(F769,[4]在职!$A:$E,5,0) -> 西南总部 | D769: =VLOOKUP(F769,[4]在职!$A:$G,7,0) -> 川东 | E769: =VLOOKUP(F769,[4]在职!$A:$M,13,0) -> 刘超 | F769: 向高涵 | G769: =VLOOKUP(F769,[4]在职!$A:$B,2,0) -> 00590 | H769: =VLOOKUP(F769,[4]在职!$A:$I,9,0) -> 二星拓展专员 | I769: 已签到 | J769: 46078 | K769: 《讲师TTT培训》 | L769: 《讲师TTT培训》
A770: 768 | B770: 2月 | C770: =VLOOKUP(F770,[4]在职!$A:$E,5,0) -> 西南总部 | D770: =VLOOKUP(F770,[4]在职!$A:$G,7,0) -> 川南 | E770: =VLOOKUP(F770,[4]在职!$A:$M,13,0) -> 刘文宇 | F770: 于强 | G770: =VLOOKUP(F770,[4]在职!$A:$B,2,0) -> 00416 | H770: =VLOOKUP(F770,[4]在职!$A:$I,9,0) -> 区域拓展总监 | I770: 已签到 | J770: 46077 | K770: 《讲师TTT培训》 | L770: 《讲师TTT培训》
A771: 769 | B771: 2月 | C771: =VLOOKUP(F771,[4]在职!$A:$E,5,0) -> 西南总部 | D771: =VLOOKUP(F771,[4]在职!$A:$G,7,0) -> 川南 | E771: =VLOOKUP(F771,[4]在职!$A:$M,13,0) -> 刘文宇 | F771: 于强 | G771: =VLOOKUP(F771,[4]在职!$A:$B,2,0) -> 00416 | H771: =VLOOKUP(F771,[4]在职!$A:$I,9,0) -> 区域拓展总监 | I771: 已签到 | J771: 46078 | K771: 《讲师TTT培训》 | L771: 《讲师TTT培训》
A772: 770 | B772: 2月 | C772: =VLOOKUP(F772,[4]在职!$A:$E,5,0) -> 西南总部 | D772: =VLOOKUP(F772,[4]在职!$A:$G,7,0) -> 川西 | E772: =VLOOKUP(F772,[4]在职!$A:$M,13,0) -> 刘文宇 | F772: 杨蓉 | G772: =VLOOKUP(F772,[4]在职!$A:$B,2,0) -> 00770 | H772: =VLOOKUP(F772,[4]在职!$A:$I,9,0) -> 区域拓展总监 | I772: 已签到 | J772: 46077 | K772: 《讲师TTT培训》 | L772: 《讲师TTT培训》
A773: 771 | B773: 2月 | C773: =VLOOKUP(F773,[4]在职!$A:$E,5,0) -> 西南总部 | D773: =VLOOKUP(F773,[4]在职!$A:$G,7,0) -> 川西 | E773: =VLOOKUP(F773,[4]在职!$A:$M,13,0) -> 刘文宇 | F773: 杨蓉 | G773: =VLOOKUP(F773,[4]在职!$A:$B,2,0) -> 00770 | H773: =VLOOKUP(F773,[4]在职!$A:$I,9,0) -> 区域拓展总监 | I773: 已签到 | J773: 46078 | K773: 《讲师TTT培训》 | L773: 《讲师TTT培训》
A774: 772 | B774: 2月 | C774: =VLOOKUP(F774,[4]在职!$A:$E,5,0) -> 甘肃 | D774: 甘肃拓展部 | E774: =VLOOKUP(F774,[4]在职!$A:$M,13,0) -> 黄芳 | F774: 雷鸣 | G774: =VLOOKUP(F774,[4]在职!$A:$B,2,0) -> 00248 | H774: =VLOOKUP(F774,[4]在职!$A:$I,9,0) -> 区域拓展总监 | I774: 已签到 | J774: 46077 | K774: 《讲师TTT培训》 | L774: 《讲师TTT培训》
A775: 773 | B775: 2月 | C775: =VLOOKUP(F775,[4]在职!$A:$E,5,0) -> 甘肃 | D775: 甘肃拓展部 | E775: =VLOOKUP(F775,[4]在职!$A:$M,13,0) -> 黄芳 | F775: 雷鸣 | G775: =VLOOKUP(F775,[4]在职!$A:$B,2,0) -> 00248 | H775: =VLOOKUP(F775,[4]在职!$A:$I,9,0) -> 区域拓展总监 | I775: 已签到 | J775: 46078 | K775: 《讲师TTT培训》 | L775: 《讲师TTT培训》
A776: 774 | B776: 2月 | C776: =VLOOKUP(F776,[4]在职!$A:$E,5,0) -> 河北 | D776: 河北拓展部 | E776: 黄芳 | F776: 张冀 | G776: =VLOOKUP(F776,[4]在职!$A:$B,2,0) -> 00039 | H776: =VLOOKUP(F776,[4]在职!$A:$I,9,0) -> 分公司总经理 | I776: 已签到 | J776: 46077 | K776: 《讲师TTT培训》 | L776: 《讲师TTT培训》
A777: 775 | B777: 2月 | C777: =VLOOKUP(F777,[4]在职!$A:$E,5,0) -> 河北 | D777: 河北拓展部 | E777: 黄芳 | F777: 张冀 | G777: =VLOOKUP(F777,[4]在职!$A:$B,2,0) -> 00039 | H777: =VLOOKUP(F777,[4]在职!$A:$I,9,0) -> 分公司总经理 | I777: 已签到 | J777: 46078 | K777: 《讲师TTT培训》 | L777: 《讲师TTT培训》
A778: 776 | B778: 2月 | C778: =VLOOKUP(F778,[4]在职!$A:$E,5,0) -> 河北 | D778: =VLOOKUP(F778,[4]在职!$A:$G,7,0) -> 0 | E778: =VLOOKUP(F778,[4]在职!$A:$M,13,0) -> 张冀 | F778: 李港一 | G778: =VLOOKUP(F778,[4]在职!$A:$B,2,0) -> 00008 | H778: =VLOOKUP(F778,[4]在职!$A:$I,9,0) -> 分公司副总经理 | I778: 已签到 | J778: 46077 | K778: 《讲师TTT培训》 | L778: 《讲师TTT培训》
A779: 777 | B779: 2月 | C779: =VLOOKUP(F779,[4]在职!$A:$E,5,0) -> 河北 | D779: =VLOOKUP(F779,[4]在职!$A:$G,7,0) -> 河北销售部 | E779: =VLOOKUP(F779,[4]在职!$A:$M,13,0) -> 李港一 | F779: 韩旭 | G779: =VLOOKUP(F779,[4]在职!$A:$B,2,0) -> 00263 | H779: =VLOOKUP(F779,[4]在职!$A:$I,9,0) -> 一星正式经理 | I779: 已签到 | J779: 46077 | K779: 《讲师TTT培训》 | L779: 《讲师TTT培训》
A780: 778 | B780: 2月 | C780: =VLOOKUP(F780,[4]在职!$A:$E,5,0) -> 河北 | D780: =VLOOKUP(F780,[4]在职!$A:$G,7,0) -> 0 | E780: =VLOOKUP(F780,[4]在职!$A:$M,13,0) -> 张冀 | F780: 李港一 | G780: =VLOOKUP(F780,[4]在职!$A:$B,2,0) -> 00008 | H780: =VLOOKUP(F780,[4]在职!$A:$I,9,0) -> 分公司副总经理 | I780: 已签到 | J780: 46078 | K780: 《讲师TTT培训》 | L780: 《讲师TTT培训》
A781: 779 | B781: 2月 | C781: =VLOOKUP(F781,[4]在职!$A:$E,5,0) -> 河北 | D781: =VLOOKUP(F781,[4]在职!$A:$G,7,0) -> 河北销售部 | E781: =VLOOKUP(F781,[4]在职!$A:$M,13,0) -> 李港一 | F781: 韩旭 | G781: =VLOOKUP(F781,[4]在职!$A:$B,2,0) -> 00263 | H781: =VLOOKUP(F781,[4]在职!$A:$I,9,0) -> 一星正式经理 | I781: 已签到 | J781: 46078 | K781: 《讲师TTT培训》 | L781: 《讲师TTT培训》
A782: 780 | B782: 2月 | C782: =VLOOKUP(F782,[4]在职!$A:$E,5,0) -> 河南 | D782: 河南拓展部 | E782: =VLOOKUP(F782,[4]在职!$A:$M,13,0) -> 黄芳 | F782: 廖静 | G782: =VLOOKUP(F782,[4]在职!$A:$B,2,0) -> 00040 | H782: =VLOOKUP(F782,[4]在职!$A:$I,9,0) -> 分公司总经理 | I782: 已签到 | J782: 46077 | K782: 《讲师TTT培训》 | L782: 《讲师TTT培训》
A783: 781 | B783: 2月 | C783: =VLOOKUP(F783,[4]在职!$A:$E,5,0) -> 河南 | D783: 河南拓展部 | E783: =VLOOKUP(F783,[4]在职!$A:$M,13,0) -> 黄芳 | F783: 廖静 | G783: =VLOOKUP(F783,[4]在职!$A:$B,2,0) -> 00040 | H783: =VLOOKUP(F783,[4]在职!$A:$I,9,0) -> 分公司总经理 | I783: 已签到 | J783: 46078 | K783: 《讲师TTT培训》 | L783: 《讲师TTT培训》
A784: 782 | B784: 2月 | C784: =VLOOKUP(F784,[4]在职!$A:$E,5,0) -> 河南 | D784: =VLOOKUP(F784,[4]在职!$A:$G,7,0) -> 河南销售部 | E784: =VLOOKUP(F784,[4]在职!$A:$M,13,0) -> 毛孝树 | F784: 周吉双 | G784: =VLOOKUP(F784,[4]在职!$A:$B,2,0) -> 00270 | H784: =VLOOKUP(F784,[4]在职!$A:$I,9,0) -> 部长 | I784: 已签到 | J784: 46077 | K784: 《讲师TTT培训》 | L784: 《讲师TTT培训》
A785: 783 | B785: 2月 | C785: =VLOOKUP(F785,[4]在职!$A:$E,5,0) -> 河南 | D785: =VLOOKUP(F785,[4]在职!$A:$G,7,0) -> 0 | E785: =VLOOKUP(F785,[4]在职!$A:$M,13,0) -> 廖静 | F785: 毛孝树 | G785: =VLOOKUP(F785,[4]在职!$A:$B,2,0) -> 00010 | H785: =VLOOKUP(F785,[4]在职!$A:$I,9,0) -> 分公司副总经理 | I785: 已签到 | J785: 46077 | K785: 《讲师TTT培训》 | L785: 《讲师TTT培训》
A786: 784 | B786: 2月 | C786: =VLOOKUP(F786,[4]在职!$A:$E,5,0) -> 河南 | D786: =VLOOKUP(F786,[4]在职!$A:$G,7,0) -> 河南销售部 | E786: =VLOOKUP(F786,[4]在职!$A:$M,13,0) -> 毛孝树 | F786: 周吉双 | G786: =VLOOKUP(F786,[4]在职!$A:$B,2,0) -> 00270 | H786: =VLOOKUP(F786,[4]在职!$A:$I,9,0) -> 部长 | I786: 已签到 | J786: 46078 | K786: 《讲师TTT培训》 | L786: 《讲师TTT培训》
...

Sheet 《授课类型》维度的参训明细
A1: 《授课类型》维度的参训明细（1-3月）
A2: 序号 | B2: 月份 | C2: 城市 | D2: 营业部 | E2: 直系上级 | F2: 应参训人姓名 | G2: 工号 | H2: 职级 | I2: 签到情况 | J2: 培训时间 | K2: 授课类型
A3: 1 | B3: 1月 | C3: 西南总部 | D3: 营业五部 | E3: 安芮内蒙古 | F3: 蒋婷 | G3: 01011 | H3: 一星销售顾问 | I3: 未签到 | J3: 46035 | K3: 销售提升训
A4: 2 | B4: 1月 | C4: 西南总部 | D4: 营业五部 | E4: 安芮内蒙古 | F4: 孙智港 | G4: 01423 | H4: 一星销售顾问 | I4: 未签到 | J4: 46035 | K4: 销售提升训
A5: 3 | B5: 1月 | C5: 西南总部 | D5: 营业五部 | E5: 安芮内蒙古 | F5: 李裕楷 | G5: 01412 | H5: 一星销售顾问 | I5: 未签到 | J5: 46035 | K5: 销售提升训
A6: 4 | B6: 1月 | C6: 西南总部 | D6: 营业二部 | E6: 柏刚 | F6: 税小蓉 | G6: 01684 | H6: 一星销售顾问 | I6: 已签到 | J6: 46035 | K6: 销售提升训
A7: 5 | B7: 1月 | C7: 陕西 | D7: 陕西2部 | E7: 李丝丝 | F7: 李松 | G7: 01689 | H7: 一星销售顾问 | I7: 已签到 | J7: 46035 | K7: 销售提升训
A8: 6 | B8: 1月 | C8: 西南总部 | D8: 营业一部 | E8: 白世根 | F8: 先波 | G8: 01512 | H8: 二星销售顾问 | I8: 未签到 | J8: 46035 | K8: 销售提升训
A9: 7 | B9: 1月 | C9: 西南总部 | D9: 营业七部 | E9: 陈彪 | F9: 田丰 | G9: 01500 | H9: 一星销售顾问 | I9: 未签到 | J9: 46035 | K9: 销售提升训
A10: 8 | B10: 1月 | C10: 西南总部 | D10: 营业四部 | E10: 陈帅 | F10: 邓孝礼 | G10: 01621 | H10: 一星销售顾问 | I10: 已签到 | J10: 46035 | K10: 销售提升训
A11: 9 | B11: 1月 | C11: 湖北 | D11: 湖北1部 | E11: 张宗铭湖北 | F11: 黄建 | G11: 01657 | H11: 一星销售顾问 | I11: 未签到 | J11: 46035 | K11: 销售提升训
A12: 10 | B12: 1月 | C12: 西南总部 | D12: 营业四部 | E12: 陈嘉文 | F12: 向巡 | G12: 01634 | H12: 一星销售顾问 | I12: 未签到 | J12: 46035 | K12: 销售提升训
A13: 11 | B13: 1月 | C13: 西南总部 | D13: 营业四部 | E13: 陈嘉文 | F13: 陈帅2 | G13: 01488 | H13: 二星销售顾问 | I13: 未签到 | J13: 46035 | K13: 销售提升训
A14: 12 | B14: 1月 | C14: 陕西 | D14: 陕西2部 | E14: 冀敏 | F14: 涂正丽 | G14: 01654 | H14: 一星销售顾问 | I14: 未签到 | J14: 46035 | K14: 销售提升训
... A329: 327 | B329: 1月 | C329: 西南总部 | D329: 职能营销 | E329: 督导部 | F329: 易束梅 | G329: 01872 | H329: 售后 | I329: 已签到 | J329: 46051 | K329: 销售新人入职培训
A330: 328 | B330: 2月 | C330: =VLOOKUP(F330,[4]在职!$A:$E,5,0) -> 集团职能 | D330: 职能总部 | E330: 黄芳 | F330: 黄芳 | G330: =VLOOKUP(F330,[4]在职!$A:$B,2,0) -> 00001 | H330: =VLOOKUP(F330,[4]在职!$A:$I,9,0) -> 总经理 | I330: 已签到 | J330: 46077 | K330: 《讲师TTT培训》
A331: 329 | B331: 2月 | C331: 宁夏 | D331: 宁夏拓展中心 | E331: 刘文宇 | F331: 黄小东 | G331: =VLOOKUP(F331,[4]在职!$A:$B,2,0) -> 00215 | H331: =VLOOKUP(F331,[4]在职!$A:$I,9,0) -> 区域拓展总监 | I331: 已签到 | J331: 46077 | K331: 《讲师TTT培训》
A332: 330 | B332: 2月 | C332: =VLOOKUP(F332,[4]在职!$A:$E,5,0) -> 西南总部 | D332: 川北 | E332: 刘文宇 | F332: 蒋婉萍 | G332: =VLOOKUP(F332,[4]在职!$A:$B,2,0) -> 00745 | H332: =VLOOKUP(F332,[4]在职!$A:$I,9,0) -> 区域拓展总监 | I332: 已签到 | J332: 46077 | K332: 《讲师TTT培训》
A333: 331 | B333: 2月 | C333: =VLOOKUP(F333,[4]在职!$A:$E,5,0) -> 集团职能 | D333: 职能总部 | E333: 黄芳 | F333: 孔群慧 | G333: =VLOOKUP(F333,[4]在职!$A:$B,2,0) -> 01918 | H333: =VLOOKUP(F333,[4]在职!$A:$I,9,0) -> 人资行政经理 | I333: 已签到 | J333: 46077 | K333: 《讲师TTT培训》
A334: 332 | B334: 2月 | C334: =VLOOKUP(F334,[4]在职!$A:$E,5,0) -> 河北 | D334: 河北销售部 | E334: 张冀 | F334: 李港一 | G334: =VLOOKUP(F334,[4]在职!$A:$B,2,0) -> 00008 | H334: =VLOOKUP(F334,[4]在职!$A:$I,9,0) -> 分公司副总经理 | I334: 已签到 | J334: 46077 | K334: 《讲师TTT培训》
A335: 333 | B335: 2月 | C335: =VLOOKUP(F335,[4]在职!$A:$E,5,0) -> 陕西 | D335: 陕西2部 | E335: 廖小朋 | F335: 李耀 | G335: =VLOOKUP(F335,[4]在职!$A:$B,2,0) -> 00077 | H335: =VLOOKUP(F335,[4]在职!$A:$I,9,0) -> 部长 | I335: 已签到 | J335: 46077 | K335: 《讲师TTT培训》
A336: 334 | B336: 2月 | C336: =VLOOKUP(F336,[4]在职!$A:$E,5,0) -> 湖南 | D336: 湖南销售部 | E336: 王超飞 | F336: 刘进 | G336: =VLOOKUP(F336,[4]在职!$A:$B,2,0) -> 00050 | H336: =VLOOKUP(F336,[4]在职!$A:$I,9,0) -> 分公司副总经理 | I336: 已签到 | J336: 46077 | K336: 《讲师TTT培训》
A337: 335 | B337: 2月 | C337: =VLOOKUP(F337,[4]在职!$A:$E,5,0) -> 河南 | D337: 河南销售部 | E337: 毛孝树 | F337: 周吉双 | G337: =VLOOKUP(F337,[4]在职!$A:$B,2,0) -> 00270 | H337: =VLOOKUP(F337,[4]在职!$A:$I,9,0) -> 部长 | I337: 已签到 | J337: 46077 | K337: 《讲师TTT培训》
A338: 336 | B338: 2月 | C338: =VLOOKUP(F338,[4]在职!$A:$E,5,0) -> 河北 | D338: 河北销售部 | E338: 李港一 | F338: 韩旭 | G338: =VLOOKUP(F338,[4]在职!$A:$B,2,0) -> 00263 | H338: =VLOOKUP(F338,[4]在职!$A:$I,9,0) -> 一星正式经理 | I338: 已签到 | J338: 46077 | K338: 《讲师TTT培训》
A339: 337 | B339: 2月 | C339: =VLOOKUP(F339,[4]在职!$A:$E,5,0) -> 西南总部 | D339: 西南拓展中心 | E339: 刘文宇 | F339: 黄伟 | G339: =VLOOKUP(F339,[4]在职!$A:$B,2,0) -> 00043 | H339: =VLOOKUP(F339,[4]在职!$A:$I,9,0) -> 分公司总经理 | I339: 已签到 | J339: 46077 | K339: 《讲师TTT培训》
A340: 338 | B340: 2月 | C340: =VLOOKUP(F340,[4]在职!$A:$E,5,0) -> 辽宁 | D340: 辽宁销售部 | E340: 聂仕平 | F340: 赖慧 | G340: =VLOOKUP(F340,[4]在职!$A:$B,2,0) -> 00016 | H340: =VLOOKUP(F340,[4]在职!$A:$I,9,0) -> 分公司副总经理 | I340: 已签到 | J340: 46077 | K340: 《讲师TTT培训》
A341: 339 | B341: 2月 | C341: =VLOOKUP(F341,[4]在职!$A:$E,5,0) -> 甘肃 | D341: 甘肃拓展部 | E341: 黄芳 | F341: 雷鸣 | G341: =VLOOKUP(F341,[4]在职!$A:$B,2,0) -> 00248 | H341: =VLOOKUP(F341,[4]在职!$A:$I,9,0) -> 区域拓展总监 | I341: 已签到 | J341: 46077 | K341: 《讲师TTT培训》
A342: 340 | B342: 2月 | C342: =VLOOKUP(F342,[4]在职!$A:$E,5,0) -> 陕西 | D342: 陕西1部 | E342: 廖小朋 | F342: 李丝丝 | G342: =VLOOKUP(F342,[4]在职!$A:$B,2,0) -> 00090 | H342: =VLOOKUP(F342,[4]在职!$A:$I,9,0) -> 部长 | I342: 已签到 | J342: 46077 | K342: 《讲师TTT培训》
A343: 341 | B343: 2月 | C343: =VLOOKUP(F343,[4]在职!$A:$E,5,0) -> 陕西 | D343: 陕西拓展部 | E343: 黄芳 | F343: 廖小朋 | G343: =VLOOKUP(F343,[4]在职!$A:$B,2,0) -> 00009 | H343: =VLOOKUP(F343,[4]在职!$A:$I,9,0) -> 分公司总经理 | I343: 已签到 | J343: 46077 | K343: 《讲师TTT培训》
... A439: 437 | B439: 2月 | C439: =VLOOKUP(F439,[4]在职!$A:$E,5,0) -> 山东 | D439: 山东销售部 | E439: 李丹 | F439: 肖佳 | G439: =VLOOKUP(F439,[4]在职!$A:$B,2,0) -> 00521 | H439: =VLOOKUP(F439,[4]在职!$A:$I,9,0) -> 一星正式经理 | I439: 已签到 | J439: 46078 | K439: 《讲师TTT培训》
A440: 438 | B440: 3月 | C440: =VLOOKUP(F440,[4]在职!$A:$E,5,0) -> 湖北 | D440: =VLOOKUP(F440,[4]在职!$A:$G,7,0) -> 湖北2部 | E440: =VLOOKUP(F440,[4]在职!$A:$M,13,0) -> 陈晓辉 | F440: 陈亮 | G440: =VLOOKUP(F440,[4]在职!$A:$B,2,0) -> 01320 | H440: =VLOOKUP(F440,[4]在职!$A:$I,9,0) -> 三星销售顾问 | I440: 已签到 | J440: 46085 | K440: B岗培训
A441: 439 | B441: 3月 | C441: =VLOOKUP(F441,[4]在职!$A:$E,5,0) -> 西南总部 | D441: =VLOOKUP(F441,[4]在职!$A:$G,7,0) -> 营业四部 | E441: =VLOOKUP(F441,[4]在职!$A:$M,13,0) -> 刘亮 | F441: 罗宁2 | G441: =VLOOKUP(F441,[4]在职!$A:$B,2,0) -> 01105 | H441: =VLOOKUP(F441,[4]在职!$A:$I,9,0) -> B岗经理 | I441: 已签到 | J441: 46085 | K441: B岗培训
A442: 440 | B442: 3月 | C442: =VLOOKUP(F442,[4]在职!$A:$E,5,0) -> 陕西 | D442: =VLOOKUP(F442,[4]在职!$A:$G,7,0) -> 陕西1部 | E442: =VLOOKUP(F442,[4]在职!$A:$M,13,0) -> 杨永梅 | F442: 何飞 | G442: =VLOOKUP(F442,[4]在职!$A:$B,2,0) -> 01158 | H442: =VLOOKUP(F442,[4]在职!$A:$I,9,0) -> 三星销售顾问 | I442: 已签到 | J442: 46085 | K442: B岗培训
A443: 441 | B443: 3月 | C443: =VLOOKUP(F443,[4]在职!$A:$E,5,0) -> 西南总部 | D443: =VLOOKUP(F443,[4]在职!$A:$G,7,0) -> 营业五部 | E443: =VLOOKUP(F443,[4]在职!$A:$M,13,0) -> 杨科 | F443: 文尤洋 | G443: =VLOOKUP(F443,[4]在职!$A:$B,2,0) -> 01351 | H443: =VLOOKUP(F443,[4]在职!$A:$I,9,0) -> B岗经理 | I443: 已签到 | J443: 46085 | K443: B岗培训
A444: 442 | B444: 3月 | C444: =VLOOKUP(F444,[4]在职!$A:$E,5,0) -> 西南总部 | D444: =VLOOKUP(F444,[4]在职!$A:$G,7,0) -> 营业二部 | E444: =VLOOKUP(F444,[4]在职!$A:$M,13,0) -> 杨芊 | F444: 杨鹏 | G444: =VLOOKUP(F444,[4]在职!$A:$B,2,0) -> 00950 | H444: =VLOOKUP(F444,[4]在职!$A:$I,9,0) -> 三星销售顾问 | I444: 已签到 | J444: 46085 | K444: B岗培训
A445: 443 | B445: 3月 | C445: =VLOOKUP(F445,[4]在职!$A:$E,5,0) -> 陕西 | D445: =VLOOKUP(F445,[4]在职!$A:$G,7,0) -> 陕西2部 | E445: =VLOOKUP(F445,[4]在职!$A:$M,13,0) -> 王辉 | F445: 王锦涛 | G445: =VLOOKUP(F445,[4]在职!$A:$B,2,0) -> 00978 | H445: =VLOOKUP(F445,[4]在职!$A:$I,9,0) -> 三星销售顾问 | I445: 已签到 | J445: 46085 | K445: B岗培训
A446: 444 | B446: 3月 | C446: =VLOOKUP(F446,[4]在职!$A:$E,5,0) -> 河南 | D446: =VLOOKUP(F446,[4]在职!$A:$G,7,0) -> 河南销售部 | E446: =VLOOKUP(F446,[4]在职!$A:$M,13,0) -> 余金梅 | F446: 顾大局 | G446: =VLOOKUP(F446,[4]在职!$A:$B,2,0) -> 01421 | H446: =VLOOKUP(F446,[4]在职!$A:$I,9,0) -> 二星销售顾问 | I446: 已签到 | J446: 46085 | K446: B岗培训
A447: 445 | B447: 3月 | C447: =VLOOKUP(F447,[4]在职!$A:$E,5,0) -> 西南总部 | D447: =VLOOKUP(F447,[4]在职!$A:$G,7,0) -> 营业七部 | E447: =VLOOKUP(F447,[4]在职!$A:$M,13,0) -> 谢沁霜 | F447: 吴洪蝶 | G447: =VLOOKUP(F447,[4]在职!$A:$B,2,0) -> 00893 | H447: =VLOOKUP(F447,[4]在职!$A:$I,9,0) -> 三星销售顾问 | I447: 已签到 | J447: 46085 | K447: B岗培训
A448: 446 | B448: 3月 | C448: =VLOOKUP(F448,[4]在职!$A:$E,5,0) -> 陕西 | D448: =VLOOKUP(F448,[4]在职!$A:$G,7,0) -> 陕西2部 | E448: =VLOOKUP(F448,[4]在职!$A:$M,13,0) -> 李耀 | F448: 王超2 | G448: =VLOOKUP(F448,[4]在职!$A:$B,2,0) -> 00945 | H448: =VLOOKUP(F448,[4]在职!$A:$I,9,0) -> 三星销售顾问 | I448: 已签到 | J448: 46085 | K448: B岗培训
A449: 447 | B449: 3月 | C449: =VLOOKUP(F449,[4]在职!$A:$E,5,0) -> 西南总部 | D449: =VLOOKUP(F449,[4]在职!$A:$G,7,0) -> 营业七部 | E449: =VLOOKUP(F449,[4]在职!$A:$M,13,0) -> 蒋杨 | F449: 霍雪毅 | G449: =VLOOKUP(F449,[4]在职!$A:$B,2,0) -> 01374 | H449: =VLOOKUP(F449,[4]在职!$A:$I,9,0) -> B岗经理 | I449: 已签到 | J449: 46085 | K449: B岗培训
...

Sheet 各类培训类型参训率（人数为维度）
A1: 各类培训类型参训率（人数为维度）1-3月
A2: 月份 | B2: 城市 | C2: 营业部 | D2: 授课类型 | E2: 培训时间 | F2: 应参训人数 | G2: 实到人数 | H2: 参训率
A3: 1月 | B3: 西南总部 | C3: 职能营销 | D3: 销售新人入职培训 | E3: 46051 | F3: =COUNTIFS([1]《授课类型》维度的参训明细!B:B,A3,[1]《授课类型》维度的参训明细!C:C,B3,[1]《授课类型》维度的参训明细!D:D,C3,[1]《授课类型》维度的参训明细!K:K,D3) -> 6 | G3: =COUNTIFS([1]《授课类型》维度的参训明细!B:B,A3,[1]《授课类型》维度的参训明细!C:C,B3,[1]《授课类型》维度的参训明细!D:D,C3,[1]《授课类型》维度的参训明细!K:K,D3,[1]《授课类型》维度的参训明细!I:I,"已签到") -> 5 | H3: =G3/F3 -> 0.83333333
A4: 1月 | B4: 湖南 | C4: 湖南销售部 | D4: 销售新人入职培训 | E4: 46051 | F4: =COUNTIFS([1]《授课类型》维度的参训明细!B:B,A4,[1]《授课类型》维度的参训明细!C:C,B4,[1]《授课类型》维度的参训明细!D:D,C4,[1]《授课类型》维度的参训明细!K:K,D4) -> 6 | G4: =COUNTIFS([1]《授课类型》维度的参训明细!B:B,A4,[1]《授课类型》维度的参训明细!C:C,B4,[1]《授课类型》维度的参训明细!D:D,C4,[1]《授课类型》维度的参训明细!K:K,D4,[1]《授课类型》维度的参训明细!I:I,"已签到") -> 3 | H4: =G4/F4 -> 0.5
A5: 1月 | B5: 陕西 | C5: 陕西2部 | D5: 销售新人入职培训 | E5: 46051 | F5: =COUNTIFS([1]《授课类型》维度的参训明细!B:B,A5,[1]《授课类型》维度的参训明细!C:C,B5,[1]《授课类型》维度的参训明细!D:D,C5,[1]《授课类型》维度的参训明细!K:K,D5) -> 4 | G5: =COUNTIFS([1]《授课类型》维度的参训明细!B:B,A5,[1]《授课类型》维度的参训明细!C:C,B5,[1]《授课类型》维度的参训明细!D:D,C5,[1]《授课类型》维度的参训明细!K:K,D5,[1]《授课类型》维度的参训明细!I:I,"已签到") -> 4 | H5: =G5/F5 -> 1
A6: 1月 | B6: 西南总部 | C6: 营业一部 | D6: 销售新人入职培训 | E6: 46051 | F6: =COUNTIFS([1]《授课类型》维度的参训明细!B:B,A6,[1]《授课类型》维度的参训明细!C:C,B6,[1]《授课类型》维度的参训明细!D:D,C6,[1]《授课类型》维度的参训明细!K:K,D6) -> 7 | G6: =COUNTIFS([1]《授课类型》维度的参训明细!B:B,A6,[1]《授课类型》维度的参训明细!C:C,B6,[1]《授课类型》维度的参训明细!D:D,C6,[1]《授课类型》维度的参训明细!K:K,D6,[1]《授课类型》维度的参训明细!I:I,"已签到") -> 4 | H6: =G6/F6 -> 0.57142857
A7: 1月 | B7: 西南总部 | C7: 营业七部 | D7: 销售新人入职培训 | E7: 46051 | F7: =COUNTIFS([1]《授课类型》维度的参训明细!B:B,A7,[1]《授课类型》维度的参训明细!C:C,B7,[1]《授课类型》维度的参训明细!D:D,C7,[1]《授课类型》维度的参训明细!K:K,D7) -> 7 | G7: =COUNTIFS([1]《授课类型》维度的参训明细!B:B,A7,[1]《授课类型》维度的参训明细!C:C,B7,[1]《授课类型》维度的参训明细!D:D,C7,[1]《授课类型》维度的参训明细!K:K,D7,[1]《授课类型》维度的参训明细!I:I,"已签到") -> 3 | H7: =G7/F7 -> 0.42857143
A8: 1月 | B8: 西南总部 | C8: 营业二部 | D8: 销售新人入职培训 | E8: 46051 | F8: =COUNTIFS([1]《授课类型》维度的参训明细!B:B,A8,[1]《授课类型》维度的参训明细!C:C,B8,[1]《授课类型》维度的参训明细!D:D,C8,[1]《授课类型》维度的参训明细!K:K,D8) -> 6 | G8: =COUNTIFS([1]《授课类型》维度的参训明细!B:B,A8,[1]《授课类型》维度的参训明细!C:C,B8,[1]《授课类型》维度的参训明细!D:D,C8,[1]《授课类型》维度的参训明细!K:K,D8,[1]《授课类型》维度的参训明细!I:I,"已签到") -> 2 | H8: =G8/F8 -> 0.33333333
A9: 1月 | B9: 河南 | C9: 河南销售部 | D9: 销售新人入职培训 | E9: 46051 | F9: =COUNTIFS([1]《授课类型》维度的参训明细!B:B,A9,[1]《授课类型》维度的参训明细!C:C,B9,[1]《授课类型》维度的参训明细!D:D,C9,[1]《授课类型》维度的参训明细!K:K,D9) -> 6 | G9: =COUNTIFS([1]《授课类型》维度的参训明细!B:B,A9,[1]《授课类型》维度的参训明细!C:C,B9,[1]《授课类型》维度的参训明细!D:D,C9,[1]《授课类型》维度的参训明细!K:K,D9,[1]《授课类型》维度的参训明细!I:I,"已签到") -> 5 | H9: =G9/F9 -> 0.83333333
A10: 1月 | B10: 西南总部 | C10: 营业三部 | D10: 销售新人入职培训 | E10: 46051 | F10: =COUNTIFS([1]《授课类型》维度的参训明细!B:B,A10,[1]《授课类型》维度的参训明细!C:C,B10,[1]《授课类型》维度的参训明细!D:D,C10,[1]《授课类型》维度的参训明细!K:K,D10) -> 7 | G10: =COUNTIFS([1]《授课类型》维度的参训明细!B:B,A10,[1]《授课类型》维度的参训明细!C:C,B10,[1]《授课类型》维度的参训明细!D:D,C10,[1]《授课类型》维度的参训明细!K:K,D10,[1]《授课类型》维度的参训明细!I:I,"已签到") -> 2 | H10: =G10/F10 -> 0.28571429
A11: 1月 | B11: 西南总部 | C11: 营业四部 | D11: 销售新人入职培训 | E11: 46051 | F11: =COUNTIFS([1]《授课类型》维度的参训明细!B:B,A11,[1]《授课类型》维度的参训明细!C:C,B11,[1]《授课类型》维度的参训明细!D:D,C11,[1]《授课类型》维度的参训明细!K:K,D11) -> 5 | G11: =COUNTIFS([1]《授课类型》维度的参训明细!B:B,A11,[1]《授课类型》维度的参训明细!C:C,B11,[1]《授课类型》维度的参训明细!D:D,C11,[1]《授课类型》维度的参训明细!K:K,D11,[1]《授课类型》维度的参训明细!I:I,"已签到") -> 1 | H11: =G11/F11 -> 0.2
A12: 1月 | B12: 湖北 | C12: 湖北2部 | D12: 销售新人入职培训 | E12: 46051 | F12: =COUNTIFS([1]《授课类型》维度的参训明细!B:B,A12,[1]《授课类型》维度的参训明细!C:C,B12,[1]《授课类型》维度的参训明细!D:D,C12,[1]《授课类型》维度的参训明细!K:K,D12) -> 1 | G12: =COUNTIFS([1]《授课类型》维度的参训明细!B:B,A12,[1]《授课类型》维度的参训明细!C:C,B12,[1]《授课类型》维度的参训明细!D:D,C12,[1]《授课类型》维度的参训明细!K:K,D12,[1]《授课类型》维度的参训明细!I:I,"已签到") -> 1 | H12: =G12/F12 -> 1
A13: 1月 | B13: 甘肃 | C13: 甘肃销售部 | D13: 销售新人入职培训 | E13: 46051 | F13: =COUNTIFS([1]《授课类型》维度的参训明细!B:B,A13,[1]《授课类型》维度的参训明细!C:C,B13,[1]《授课类型》维度的参训明细!D:D,C13,[1]《授课类型》维度的参训明细!K:K,D13) -> 1 | G13: =COUNTIFS([1]《授课类型》维度的参训明细!B:B,A13,[1]《授课类型》维度的参训明细!C:C,B13,[1]《授课类型》维度的参训明细!D:D,C13,[1]《授课类型》维度的参训明细!K:K,D13,[1]《授课类型》维度的参训明细!I:I,"已签到") -> 1 | H13: =G13/F13 -> 1
A14: 1月 | B14: 山东 | C14: 山东销售部 | D14: 销售新人入职培训 | E14: 46051 | F14: =COUNTIFS([1]《授课类型》维度的参训明细!B:B,A14,[1]《授课类型》维度的参训明细!C:C,B14,[1]《授课类型》维度的参训明细!D:D,C14,[1]《授课类型》维度的参训明细!K:K,D14) -> 2 | G14: =COUNTIFS([1]《授课类型》维度的参训明细!B:B,A14,[1]《授课类型》维度的参训明细!C:C,B14,[1]《授课类型》维度的参训明细!D:D,C14,[1]《授课类型》维度的参训明细!K:K,D14,[1]《授课类型》维度的参训明细!I:I,"已签到") -> 2 | H14: =G14/F14 -> 1
